Workbook
Name OLE_LINK1: #REF!
Name OLE_LINK1: #REF!
Name rngCeilingAm: #REF!
Name rngCeilingCnt: #REF!
Name rngCeilingVal: #REF!
Name rngFloorAm: #REF!
Name rngFloorCnt: #REF!
Name rngFloorVal: #REF!
Name rngMaximum: #REF!
Name rngMinimum: #REF!
Name rngNegCnt: #REF!
Name rngNegVal: #REF!
Name rngRecInDwnld: #REF!
Name rngRecInDwnldVal: #REF!
Name rngSmpSz1: #REF!
Name rngSmpSz2: #REF!
Name rngSmpSz3: #REF!
Name rngSmpSz4: #REF!
Name rngSmpSz5: #REF!
Name rngSmpSz6: #REF!
Name rngStr1BrkVal: #REF!
Name rngStr2BrkVal: #REF!
Name rngStr3BrkVal: #REF!
Name rngStr4BrkVal: #REF!
Name rngStr5BrkVal: #REF!
Name rngUnitsSmpCnt: #REF!
Name rngUnitsSmpVal: #REF!
Name rngUnSz1: #REF!
Name rngUnSz1Val: #REF!
Name rngUnSz2: #REF!
Name rngUnSz2Val: #REF!
Name rngUnSz3: #REF!
Name rngUnSz3Val: #REF!
Name rngUnSz4: #REF!
Name rngUnSz4Val: #REF!
Name rngUnSz5: #REF!
Name rngUnSz5Val: #REF!
Name rngUnSz6: #REF!
Name rngUnSz6Val: #REF!

Sheet Guidelines
A1: AGENCY | B1: Local | C1: OOS | D1: Agency is the Applicant | E1: No Agency | F1: Local | G1: OOS | H1: Agency is the Applicant | I1: No Agency
A2: PRODCO | B2: Local | C2: Local | D2: Local | E2: Local | F2: OOS | G2: OOS | H2: OOS | I2: OOS
A3: Crew Payroll Tab | B3: Enter all back up | C3: Enter all back up | D3: Enter all back up | E3: Enter all back up | F3: Enter all back up | G3: Enter all back up | H3: Enter all back up | I3: Enter all back up
A4: Crew Expenses Tab | B4: Enter one line & NO-IL | C4: Enter one line & NO-IL | D4: Enter one line & NO-IL | E4: Enter one line & NO-IL | F4: Enter one line & NO-IL, except break out Receipts/Invoices ≥$200.00 paid with CC | G4: Enter all back up | H4: Enter all back up | I4: Enter all back up
A5: Production Tab | B5: Enter Vendor PO #, Name, Amount, Description, link & NO-IL | C5: Enter Vendor PO #, Name, Amount, Description, link & NO-IL | D5: Enter Vendor PO #, Name, Amount, Description, link & NO-IL | E5: Enter Vendor PO #, Name, Amount, Description, link & NO-IL | F5: Enter all back up | G5: Enter all back up | H5: Enter all back up | I5: Enter all back up
A6: Prod CC Tab | B6: Enter one line & NO-IL | C6: Enter one line & NO-IL | D6: Enter one line & NO-IL | E6: Enter one line & NO-IL | F6: Enter one line & NO-IL, except break out Receipts/Invoices ≥$200.00 paid with CC | G6: Enter all back up | H6: Enter all back up | I6: Enter all back up
A7: Petty Cash Tab | B7: Enter one line & NO-IL | C7: Enter one line & NO-IL | D7: Enter one line & NO-IL | E7: Enter one line & NO-IL | F7: Enter one line & NO-IL, except break out Receipts/Invoices ≥$200.00 paid with CC | G7: Enter all back up | H7: Enter all back up | I7: Enter all back up
A8: Client Billings | B8: Request a Summary Invoice (s) | C8: Request a Summary Invoice (s) | D8: Request a Summary Invoice (s) | E8: Request a Summary Invoice (s) | F8: Request a Summary Invoice (s) | G8: Request a Summary Invoice (s) | H8: Request a Summary Invoice (s) | I8: Request a Summary Invoice (s)
A10: Split Receipts | B10: û | C10: x | D10: x | E10: x | F10: Needed if qualified ProdCo exps are less than 50% of ProdCo billings | G10: ü | H10: ü | I10: ü
A11: Alcohol Split Receipts | B11: û | C11: û | D11: û | E11: û | F11: ü | G11: ü | H11: ü | I11: ü
A12: Hotel Charges Summary | B12: û | C12: û | D12: û | E12: û | F12: Needed if qualified ProdCo exps are less than 50% of ProdCo billings; when meals are $300 and above | G12: When meals are $300 and above | H12: When meals are $300 and above | I12: When meals are $300 and above
A14: Local Agency - will qualify client billings less deductions
A15: Local ProdCo - will qualify ProdCo billings
A16: Local Agency - OOS ProdCo - can still qualify entire ProdCo billings, regardless of qualified ProdCo Vendors (at least 50%)
A18: WHAT'S INCLUDED IN THE CPA WORKBOOK?
A19: AGENCY
A20: Client Billings - Agency | B20: Include, deduct OOS agency exps if detailed billings | C20: Exclude, submit billings in the State Sub Folder | D20: Exclude | E20: N/A | F20: Include, deduct OOS agency exps if detailed billings | G20: Exclude, submit billings in the State Sub Folder | H20: Exclude | I20: N/A
A21: Agency IL Vendors | B21: Include | C21: Include | D21: Include | E21: N/A | F21: Include | G21: Include | H21: Include | I21: N/A
A22: Agency Hours Letter | B22: Include, will increase qualified amount if with retainer fee | C22: N/A | D22: Include, will increase qualified amount if with retainer fee | E22: N/A | F22: Include, will increase qualified amount if with retainer fee | G22: N/A | H22: Include, will increase qualified amount if with retainer fee | I22: N/A
A23: Talent | B23: Include - PTIP amounts in Talent Tab; Qualify entire invoice amount if at least 1 talent qualifies in the Client Billing; will affect total amount if Client Billing is detailed | C23: Include, use PTIP report as reference | D23: Include, use PTIP report as reference | E23: N/A | F23: Include - PTIP amounts in Talent Tab; Qualify entire invoice amount if at least 1 talent qualifies in the Client Billing; will affect total amount if Client Billing is detailed | G23: Include, will increase amount qualified | H23: Include, will increase amount qualified | I23: N/A
A24: Agency Exp Reports | B24: Include if detailed billings; Exclude if summary billings | C24: Include | D24: Include | E24: N/A | F24: Include if detailed billings; Exclude if summary billings | G24: Include | H24: Include | I24: N/A
A25: OOS Crew - paid by Agency | B25: Include if detailed client billings; Exclude if summary billings | C25: Include | D25: Include | E25: Include if detailed client billings; Exclude if summary billings | F25: Exclude | G25: Include | H25: Include | I25: N/A
A27: PRODCO
A28: ProdCo Billings | B28: Include | C28: Include | D28: Include | E28: Include | F28: Exclude, submit billings in the State Submission folder | G28: Exclude, submit billings in the State Sub Folder | H28: Exclude, submit billings in the State Sub Folder | I28: N/A
A29: ProdCo IL Vendors | B29: Exclude | C29: Exclude | D29: Exclude | E29: Exclude | F29: Include | G29: Include | H29: Include | I29: Include
A30: Prod Crew Payroll | B30: Include, will be deducted from Total Vendor Expenses (CPA Presentation) | C30: Include, will be deducted from Total Vendor Expenses (CPA Presentation) | D30: Include, will be deducted from Total Vendor Expenses (CPA Presentation) | E30: Include, will be deducted from Total Vendor Expenses (CPA Presentation) | F30: Include, will be deducted from Total Vendor Expenses (CPA Presentation) | G30: Include, will increase qualified spend | H30: Include, will increase qualified spend | I30: Include, will be deducted from Total Vendor Expenses (CPA Presentation)
A31: Prod CC | B31: Exclude | C31: Exclude | D31: Exclude | E31: Exclude | F31: Needed if qualified ProdCo exps are less than 50% of ProdCo billings | G31: Include | H31: Include | I31: Include
A32: Prod Petty Cash | B32: Exclude | C32: Exclude | D32: Exclude | E32: Exclude | F32: Needed if qualified ProdCo exps are less than 50% of ProdCo billings | G32: Include | H32: Include | I32: Include
A33: Crew Expenses | B33: Exclude | C33: Exclude | D33: Exclude | E33: Exclude | F33: Needed if qualified ProdCo exps are less than 50% of ProdCo billings | G33: Include | H33: Include | I33: Include
A34: Talent | B34: Include (will be deducted from Total Vendor Expenses) | C34: Include (will be deducted from Total Vendor Expenses) | D34: Include | E34: Include (will be deducted from Total Vendor Expenses) | F34: Include | G34: Include | H34: Include | I34: Include
A35: OOS Crew - paid by ProdCo | B35: Exclude | C35: Exclude | D35: Exclude | E35: Exclude | F35: Needed if qualified ProdCo exps are less than 50% of ProdCo billings | G35: Include | H35: Include | I35: Include

Sheet Comm Summary (O-L,N-L)
A1: TPC Commercial Incentives Service
A2: Commercial Project Summary
B4: Project Description | F4: State: | H4: Illinois | X4: ECS Company code: | Y4: Elite CIS
B5: Project Title:
B7: Award Date:
B8: Pre Pro Date: | H8: LIVE ACTION | X8: Rebate Estimate Analysis | AB8: STILL
B9: Shoot Date:
B10: Production Wrap Date | H10: SUBMITTED EXPENSES | N10: QUALIFIED EXPENSES | T10: Pending | V10: DNQ | X10: Amount | Y10: Difference
B11: Post Production Date: | H11: PRODUCTION COMPANY | AB11: To have additional columns here if there's another shoot/ production (to not create another workbook)
B12: ProdCo Job Type(s): | H12: Crew Payroll | K12: ='Crew Payroll'!AE45 -> 0 | N12: Total Crew Payroll | Q12: =P13+P14 -> 0 | T12: ='Crew Payroll'!U53 -> 0 | V12: =K12-(Q12+T12) -> 0 | AB12: Create Crew Payroll, Production, and other applicable tabs and create formulas to get total Submitted and Qualified costs.
B13: ProdCo Job Notes: | O13: IL Crew Payroll | P13: ='Crew Payroll'!S53 -> 0
B14: OOS Shoot Job Type & Location | O14: OOS Crew | P14: ='Crew Payroll'!S54 -> 0
B15: OOS Shoot Date(s): | H15: ProdCo Sub-Vendors | K15: =#REF! -> #REF! | N15: ProdCo Sub-Vendors | Q15: =#REF! -> #REF! | T15: =#REF! -> #REF! | V15: =K15-(Q15+T15) -> #REF!
H16: Prod - Petty Cash | K16: =#REF! -> #REF! | N16: Prod - Petty Cash | Q16: =#REF! -> #REF! | T16: =#REF! -> #REF! | V16: =K16-(Q16+T16) -> #REF!
B17: Client: | H17: Prod - Credit Card | K17: =#REF! -> #REF! | N17: Prod - Credit Card | Q17: =#REF! -> #REF! | T17: =#REF! -> #REF! | V17: =K17-(Q17+T17) -> #REF!
B18: Client Brand & Product: | H18: Prod - Exp Reports | K18: =#REF! -> #REF! | N18: Prod - Exp Reports | Q18: =#REF! -> #REF! | T18: =#REF! -> #REF! | V18: =K18-(Q18+T18) -> #REF!
B19: Agency:
B20: Production Company: | D20: OOS Agency or No Agency | H20: Total Talent | K20: =SUM('Talent & Extras'!T63) -> 0 | N20: Total Talent | Q20: ='Talent & Extras'!N81 -> 0 | T20: ='Talent & Extras'!M69 -> 0 | V20: =K20-(Q20+T20) -> 0
B21: Subcontracted ProdCo: | D21: Local ProdCo (Motion) | I21: Talent Payroll | J21: ='Talent & Extras'!Q69 -> 0 | O21: Talent Payroll | P21: ='Talent & Extras'!D69 -> 0
B22: OOS Shoot Prod Company: | D22: Local ProdCo (Still) | I22: Extras Payroll | J22: ='Talent & Extras'!C71 -> 0 | O22: Extras Payroll | P22: ='Talent & Extras'!D70 -> 0
B23: Crew Payroll Company: | O23: Two (2) OOS Talent | P23: ='Talent & Extras'!R69 -> 0
B24: Celebrity Payroll Company: | O24: Handling Fees | P24: ='Agency Sub-Vendors'!M69 -> 0
B25: Talent Payroll Company: | O25: Agency Fees | P25: ='Agency Sub-Vendors'!M68 -> 0
B26: Production Insurance: | H26: Agency Sub-Vendors | K26: ='Agency Sub-Vendors'!M63 -> 0 | N26: Total Sub-Vendors | Q26: ='Agency Sub-Vendors'!M60 -> 0 | T26: ='Agency Sub-Vendors'!M61 -> 0 | V26: =K26-(Q26+T26) -> 0
B27: Other Payor 2: | H27: Agency Hours | K27: ='Agency Hours'!T43 -> 0 | N27: Normal Agency Hours | Q27: ='Agency Hours'!Q71 -> 0 | T27: ='Agency Hours'!O43 -> 0 | V27: =K27-(Q27+T27) -> 0
B28: Other Payor 3: | O28: IL Crew | P28: ='Agency Hours'!Q58 -> 0
O29: OOS Crew | P29: ='Agency Hours'!R43 -> 0
B30: Celebrity Name(s):
I31: Retainer Billings | J31: ='Agency Hours'!J49 -> 0 | O31: Retainer Billings | P31: ='Agency Hours'!S49 -> 0 | U31: ='Agency Hours'!O49 -> 0 | V31: =J31-(P31+U31) -> 0
B32: Agency Job Description:
B33: Agency Job Name: | H33: Prod Agency Hours | K33: ='Agency Hours'!Q68 -> 0 | N33: Production Agency Hours | Q33: ='Agency Hours'!Q64+'Agency Hours'!Q65 -> 0 | T33: ='Agency Hours'!O55 -> 0 | V33: =K33-(Q33+T33) -> 0
B34: Agency Job Number: | O34: IL Crew | P34: ='Agency Hours'!S55 -> 0
O35: OOS Crew | P35: ='Agency Hours'!R55 -> 0
C36: AICP Bid | D36: 0
C37: Agency Estimate | D37: 0 | H37: Agency Exp. Report | K37: =#REF! -> #REF! | N37: Agency Exp. Report | Q37: =#REF! -> #REF! | T37: =#REF! -> #REF! | V37: =K37-(Q37+T37) -> #REF!
C38: Final Script/Storyboard Date | H38: Client - Crew | K38: 0 | N38: Client | Q38: 0 | T38: 0 | V38: =K38-(Q38+T38) -> 0
C39: Application & Boards | H39: Client - Sub-Vendors | K39: 0 | N39: Client - Sub-Vendors | Q39: 0 | T39: 0 | V39: =K39-(Q39+T39) -> 0
C40: APC | H40: Consultant | K40: 0 | N40: Consultant | Q40: 0 | T40: 0 | V40: =K40-(Q40+T40) -> 0
C41: Pre-Production Book | I41: Consultant Retainer Fee | J41: 0 | O41: Consultant Retainer Fee | P41: 0 | U41: 0 | V41: 0
C42: Call Sheet | H42: CPA Fee | K42: 0 | N42: CPA Fee | Q42: 0 | U42: 0 | V42: =K42-(Q42+T42) -> 0
...

Sheet Comm Summary (A-L)
A1: TPC Commercial Incentives Service
A2: Commercial Project Summary
B4: Project Description | C4: =CONCATENATE(C17, " ",C18, " ",C5) -> Digitas "2022 Q3 Eggo Liege TV" | F4: State: | H4: Illinois | V4: ECS Company code: | W4: Elite CIS
B5: Project Title: | C5: "2022 Q3 Eggo Liege TV"
B7: Award Date:
B8: Pre Pro Date: | H8: LIVE ACTION | X8: Rebate Estimate Analysis | AB8: STILL
B9: Shoot Date:
B10: Production Wrap Date | H10: SUBMITTED EXPENSES | N10: QUALIFIED EXPENSES | T10: Pending | V10: DNQ | X10: Amount | Y10: Difference
B11: Post Production Date: | H11: PRODUCTION COMPANY | AB11: To have additional columns here if there's another shoot/ production (to not create another workbook)
B12: ProdCo Job Type(s): | H12: Crew Payroll | K12: ='Crew Payroll'!AE45 -> 0 | N12: Total Crew Payroll | Q12: =P13+P14 -> 0 | T12: ='Crew Payroll'!U53 -> 0 | V12: =K12-(Q12+T12) -> 0 | AB12: Create Crew Payroll, Production, and other applicable tabs and create formulas to get total Submitted and Qualified costs.
B13: ProdCo Job Notes: | O13: IL Crew Payroll | P13: ='Crew Payroll'!S53 -> 0
B14: OOS Shoot Job Type & Location | O14: OOS Crew | P14: ='Crew Payroll'!S54 -> 0
B15: OOS Shoot Date(s): | H15: ProdCo Sub-Vendors | K15: =#REF! -> #REF! | N15: ProdCo Sub-Vendors | Q15: =#REF! -> #REF! | T15: =#REF! -> #REF! | V15: =K15-(Q15+T15) -> #REF!
H16: Prod - Petty Cash | K16: =#REF! -> #REF! | N16: Prod - Petty Cash | Q16: =#REF! -> #REF! | T16: =#REF! -> #REF! | V16: =K16-(Q16+T16) -> #REF!
B17: Client: | C17: Digitas | H17: Prod - Credit Card | K17: =#REF! -> #REF! | N17: Prod - Credit Card | Q17: =#REF! -> #REF! | T17: =#REF! -> #REF! | V17: =K17-(Q17+T17) -> #REF!
B18: Client Brand & Product: | H18: Prod - Exp Reports | K18: =#REF! -> #REF! | N18: Prod - Exp Reports | Q18: =#REF! -> #REF! | T18: =#REF! -> #REF! | V18: =K18-(Q18+T18) -> #REF!
B19: Agency: | C19: Digitas | D19: Local Agency or Agency is Applicant | Z19: AICP less identified OOS
B20: Production Company: | C20: Picrow, Inc | D20: Local ProdCo (Motion) | H20: Total Talent | K20: =SUM('Talent & Extras'!T63) -> 0 | N20: Total Talent | Q20: ='Talent & Extras'!N81 -> 0 | T20: ='Talent & Extras'!M69 -> 0 | V20: =K20-(Q20+T20) -> 0
B21: Subcontracted ProdCo: | C21: Gabe Sanchez | D21: Local ProdCo (Still) | I21: Talent Payroll | J21: ='Talent & Extras'!Q69 -> 0 | O21: Talent Payroll | P21: ='Talent & Extras'!D69 -> 0
B22: OOS Shoot Prod Company: | I22: Extras Payroll | J22: ='Talent & Extras'!C71 -> 0 | O22: Extras Payroll | P22: ='Talent & Extras'!D70 -> 0
B23: Crew Payroll Company: | C23: Greenslate | O23: Two (2) OOS Talent | P23: ='Talent & Extras'!R69 -> 0
B24: Celebrity Payroll Company: | O24: Handling Fees | P24: ='Agency Sub-Vendors'!M69 -> 0
B25: Talent Payroll Company: | C25: Extreme Reach Talent, Inc | O25: Agency Fees | P25: ='Agency Sub-Vendors'!M68 -> 0
B26: Production Insurance: | H26: Agency Sub-Vendors | K26: ='Agency Sub-Vendors'!M63 -> 0 | N26: Total Sub-Vendors | Q26: ='Agency Sub-Vendors'!M60 -> 0 | T26: ='Agency Sub-Vendors'!M61 -> 0 | V26: =K26-(Q26+T26) -> 0
B27: Other Payor 2: | H27: Agency Hours | K27: ='Agency Hours'!T43 -> 0 | N27: Normal Agency Hours | Q27: ='Agency Hours'!Q71 -> 0 | T27: ='Agency Hours'!O43 -> 0 | V27: =K27-(Q27+T27) -> 0
B28: Other Payor 3: | O28: IL Crew | P28: ='Agency Hours'!Q58 -> 0
O29: OOS Crew | P29: ='Agency Hours'!R43 -> 0
B30: Celebrity Name(s):
I31: Retainer Billings | J31: ='Agency Hours'!J49 -> 0 | O31: Retainer Billings | P31: ='Agency Hours'!S49 -> 0 | U31: ='Agency Hours'!O49 -> 0 | V31: =J31-(P31+U31) -> 0
B32: Agency Job Description:
B33: Agency Job Name: | H33: Prod Agency Hours | K33: ='Agency Hours'!Q68 -> 0 | N33: Production Agency Hours | Q33: ='Agency Hours'!Q64+'Agency Hours'!Q65 -> 0 | T33: ='Agency Hours'!O55 -> 0 | V33: =K33-(Q33+T33) -> 0
B34: Agency Job Number: | O34: IL Crew | P34: ='Agency Hours'!S55 -> 0
O35: OOS Crew | P35: ='Agency Hours'!R55 -> 0
C36: AICP Bid | D36: 300358
C37: Agency Estimate | H37: Agency Exp. Report | K37: =#REF! -> #REF! | N37: Agency Exp. Report | Q37: =#REF! -> #REF! | T37: =#REF! -> #REF! | V37: =K37-(Q37+T37) -> #REF!
C38: Final Script/Storyboard Date | H38: Client - Crew | K38: =#REF! -> #REF! | N38: Client | Q38: =#REF!+#REF! -> #REF! | T38: =#REF! -> #REF! | V38: =K38-(Q38+T38) -> #REF!
C39: Application & Boards | H39: Client - Sub-Vendors | K39: =#REF! -> #REF! | N39: Client - Sub-Vendors | Q39: =#REF! -> #REF! | T39: =#REF! -> #REF! | V39: =K39-(Q39+T39) -> #REF!
C40: APC | H40: Consultant | K40: =#REF! -> #REF! | N40: Consultant | Q40: =#REF! -> #REF! | T40: =SUM(T12,T15:T18,T20,T26:T27,T34:T37) -> #REF! | V40: =K40-(Q40+T40) -> #REF!
C41: Pre-Production Book | I41: Consultant Retainer Fee | J41: =#REF! -> #REF! | O41: Consultant Retainer Fee | P41: =#REF! -> #REF! | U41: =#REF! -> #REF! | V41: =J41-(P41+U41) -> #REF!
C42: Call Sheet | H42: CPA Fee | K42: 0 | N42: CPA Fee | Q42: 0 | V42: =K42-(Q42+T42) -> 0
...

Sheet Comm Summary (L-L, L-O)
A1: TPC Commercial Incentives Service
A2: Commercial Project Summary
B4: Project Description | C4: =CONCATENATE(C17, " ",C18, " ",C5) -> "2022 Q3 Eggo Liege TV" | F4: State: | H4: Illinois | X4: ECS Company code: | Y4: Elite CIS
B5: Project Title: | C5: "2022 Q3 Eggo Liege TV"
B7: Award Date:
B8: Pre Pro Date: | H8: LIVE ACTION | X8: Rebate Estimate Analysis | AB8: STILL
B9: Shoot Date:
B10: Production Wrap Date | H10: SUBMITTED EXPENSES | N10: QUALIFIED EXPENSES | T10: Pending | V10: DNQ | X10: Amount | Y10: Difference
B11: Post Production Date: | H11: PRODUCTION COMPANY | AB11: To have additional columns here if there's another shoot/ production (to not create another workbook)
B12: ProdCo Job Type(s): | H12: Crew Payroll | K12: ='Crew Payroll'!AE45 -> 0 | N12: Total Crew Payroll | Q12: =P13+P14 -> 0 | T12: ='Crew Payroll'!U53 -> 0 | V12: =K12-(Q12+T12) -> 0 | AB12: Create Crew Payroll, Production, and other applicable tabs and create formulas to get total Submitted and Qualified costs.
B13: ProdCo Job Notes: | O13: IL Crew Payroll | P13: ='Crew Payroll'!S53 -> 0
B14: OOS Shoot Job Type & Location | O14: OOS Crew | P14: ='Crew Payroll'!S54 -> 0
B15: OOS Shoot Date(s): | H15: ProdCo Sub-Vendors | K15: =#REF! -> #REF! | N15: ProdCo Sub-Vendors | Q15: =#REF! -> #REF! | T15: =#REF! -> #REF! | V15: =K15-(Q15+T15) -> #REF!
H16: Prod - Petty Cash | K16: =#REF! -> #REF! | N16: Prod - Petty Cash | Q16: =#REF! -> #REF! | T16: =#REF! -> #REF! | V16: =K16-(Q16+T16) -> #REF!
B17: Client: | H17: Prod - Credit Card | K17: =#REF! -> #REF! | N17: Prod - Credit Card | Q17: =#REF! -> #REF! | T17: =#REF! -> #REF! | V17: =K17-(Q17+T17) -> #REF!
B18: Client Brand & Product: | H18: Prod - Exp Reports | K18: =#REF! -> #REF! | N18: Prod - Exp Reports | Q18: =#REF! -> #REF! | T18: =#REF! -> #REF! | V18: =K18-(Q18+T18) -> #REF!
B19: Agency: | D19: Local Agency | Z19: AICP less identified OOS
B20: Production Company: | D20: Local or OOS (State) - Motion or Still | H20: Total Talent | K20: =SUM('Talent & Extras'!T63) -> 0 | N20: Total Talent | Q20: ='Talent & Extras'!N81 -> 0 | T20: ='Talent & Extras'!M69 -> 0 | V20: =K20-(Q20+T20) -> 0
B21: Subcontracted ProdCo: | D21: Local or OOS (State) - Motion or Still | I21: Talent Payroll | J21: ='Talent & Extras'!Q69 -> 0 | O21: Talent Payroll | P21: ='Talent & Extras'!D69 -> 0
B22: OOS Shoot Prod Company: | I22: Extras Payroll | J22: ='Talent & Extras'!C71 -> 0 | O22: Extras Payroll | P22: ='Talent & Extras'!D70 -> 0
B23: Crew Payroll Company: | O23: Two (2) OOS Talent | P23: ='Talent & Extras'!R69 -> 0
B24: Celebrity Payroll Company: | O24: Handling Fees | P24: ='Agency Sub-Vendors'!M69 -> 0
B25: Talent Payroll Company: | O25: Agency Fees | P25: ='Agency Sub-Vendors'!M68 -> 0
B26: Production Insurance: | H26: Agency Sub-Vendors | K26: ='Agency Sub-Vendors'!M63 -> 0 | N26: Total Sub-Vendors | Q26: ='Agency Sub-Vendors'!M60 -> 0 | T26: ='Agency Sub-Vendors'!M61 -> 0 | V26: =K26-(Q26+T26) -> 0
B27: Other Payor 2: | H27: Agency Hours | K27: ='Agency Hours'!T43 -> 0 | N27: Normal Agency Hours | Q27: ='Agency Hours'!Q71 -> 0 | T27: ='Agency Hours'!O43 -> 0 | V27: =K27-(Q27+T27) -> 0
B28: Other Payor 3: | O28: IL Crew | P28: ='Agency Hours'!Q58 -> 0
O29: OOS Crew | P29: ='Agency Hours'!R43 -> 0
B30: Celebrity Name(s):
I31: Retainer Billings | J31: ='Agency Hours'!J49 -> 0 | O31: Retainer Billings | P31: ='Agency Hours'!S49 -> 0 | U31: ='Agency Hours'!O49 -> 0 | V31: =J31-(P31+U31) -> 0
B32: Agency Job Description:
B33: Agency Job Name: | H33: Prod Agency Hours | K33: ='Agency Hours'!Q68 -> 0 | N33: Production Agency Hours | Q33: ='Agency Hours'!Q64+'Agency Hours'!Q65 -> 0 | T33: ='Agency Hours'!O55 -> 0 | V33: =K33-(Q33+T33) -> 0
B34: Agency Job Number: | O34: IL Crew | P34: ='Agency Hours'!S55 -> 0
O35: OOS Crew | P35: ='Agency Hours'!R55 -> 0
C36: AICP Bid
C37: Agency Estimate | H37: Agency Exp. Report | K37: =#REF! -> #REF! | N37: Agency Exp. Report | Q37: =#REF! -> #REF! | T37: =#REF! -> #REF! | V37: =K37-(Q37+T37) -> #REF!
C38: Final Script/Storyboard Date | H38: Client - Crew | K38: =#REF! -> #REF! | N38: Client | Q38: =#REF!+#REF! -> #REF! | T38: =#REF! -> #REF! | V38: =K38-(Q38+T38) -> #REF!
C39: Application & Boards | H39: Client - Sub-Vendors | K39: =#REF! -> #REF! | N39: Client - Sub-Vendors | Q39: =#REF! -> #REF! | T39: =#REF! -> #REF! | V39: =K39-(Q39+T39) -> #REF!
C40: APC | H40: Consultant | K40: =#REF! -> #REF! | N40: Consultant | Q40: =#REF! -> #REF! | T40: =SUM(T12,T15:T18,T20,T26:T27,T34:T37) -> #REF! | V40: =K40-(Q40+T40) -> #REF!
C41: Pre-Production Book | I41: Consultant Retainer Fee | J41: =#REF! -> #REF! | O41: Consultant Retainer Fee | P41: =#REF! -> #REF! | U41: =#REF! -> #REF! | V41: =J41-(P41+U41) -> #REF!
C42: Call Sheet | H42: CPA Fee | K42: 0 | N42: CPA Fee | Q42: 0 | V42: =K42-(Q42+T42) -> 0
...

Sheet Billings
A1: TPC Commercial Incentives Service
A2: Commercial Project Billings Summary
B7: ITEM | C7: Qualify | D7: Vendor Name | E7: Vendor Type | F7: Job Type | G7: State | H7: Description | I7: Details | J7: Invoice Date | K7: Invoice # | L7: Eligible Total | M7: Project Fee | N7: Address | O7: City | P7: State | Q7: Zip | R7: Received Invoice | S7: POP | T7: Payment Date | U7: Payment Method | V7: W-9 | W7: Job Number | X7: Notes | Z7: VENDOR NAME | AA7: DESCRIPTION | AB7: ADDRESS | AC7: CITY | AD7: ZIP | AE7: INVOICE DATE | AF7: INVOICE NUMBER | AG7: AMOUNT | AI7: PAYMENT DATE | AJ7: PAYMENT METHOD
B8: 1 | L8: 0 | Z8: =D8 -> 0 | AA8: =H8 -> 0 | AB8: =N8 -> 0 | AC8: =O7 -> City | AD8: =Q8 -> 0 | AE8: =J8 -> 0 | AF8: =K8 -> 0 | AG8: =L8 -> 0 | AI8: =T8 -> 0 | AJ8: =U8 -> 0
B9: 2 | L9: 0 | Z9: =D9 -> 0 | AA9: =H9 -> 0 | AB9: =N9 -> 0 | AC9: =O8 -> 0 | AD9: =Q9 -> 0 | AE9: =J9 -> 0 | AF9: =K9 -> 0 | AG9: =L9 -> 0 | AI9: =T9 -> 0 | AJ9: =U9 -> 0
B10: 3 | L10: 0 | Z10: =D10 -> 0 | AA10: =H10 -> 0 | AB10: =N10 -> 0 | AC10: =O9 -> 0 | AD10: =Q10 -> 0 | AE10: =J10 -> 0 | AF10: =K10 -> 0 | AG10: =L10 -> 0 | AI10: =T10 -> 0 | AJ10: =U10 -> 0
B11: 4 | L11: 0 | Z11: =D11 -> 0 | AA11: =H11 -> 0 | AB11: =N11 -> 0 | AC11: =O10 -> 0 | AD11: =Q11 -> 0 | AE11: =J11 -> 0 | AF11: =K11 -> 0 | AG11: =L11 -> 0 | AI11: =T11 -> 0 | AJ11: =U11 -> 0
B12: 5 | L12: 0 | Z12: =D12 -> 0 | AA12: =H12 -> 0 | AB12: =N12 -> 0 | AC12: =O11 -> 0 | AD12: =Q12 -> 0 | AE12: =J12 -> 0 | AF12: =K12 -> 0 | AG12: =L12 -> 0 | AI12: =T12 -> 0 | AJ12: =U12 -> 0
B13: 6 | L13: 0 | Z13: =D13 -> 0 | AA13: =H13 -> 0 | AB13: =N13 -> 0 | AC13: =O12 -> 0 | AD13: =Q13 -> 0 | AE13: =J13 -> 0 | AF13: =K13 -> 0 | AG13: =L13 -> 0 | AI13: =T13 -> 0 | AJ13: =U13 -> 0
B14: 7 | L14: 0 | Z14: =D14 -> 0 | AA14: =H14 -> 0 | AB14: =N14 -> 0 | AC14: =O13 -> 0 | AD14: =Q14 -> 0 | AE14: =J14 -> 0 | AF14: =K14 -> 0 | AG14: =L14 -> 0 | AI14: =T14 -> 0 | AJ14: =U14 -> 0
B15: 8 | L15: 0 | Z15: =D15 -> 0 | AA15: =H15 -> 0 | AB15: =N15 -> 0 | AC15: =O14 -> 0 | AD15: =Q15 -> 0 | AE15: =J15 -> 0 | AF15: =K15 -> 0 | AG15: =L15 -> 0 | AI15: =T15 -> 0 | AJ15: =U15 -> 0
B16: 9 | L16: 0 | Z16: =D16 -> 0 | AA16: =H16 -> 0 | AB16: =N16 -> 0 | AC16: =O11 -> 0 | AD16: =Q16 -> 0 | AE16: =J16 -> 0 | AF16: =K16 -> 0 | AG16: =L16 -> 0 | AI16: =T16 -> 0 | AJ16: =U16 -> 0
B17: 10 | L17: 0 | Z17: =D17 -> 0 | AA17: =H17 -> 0 | AB17: =N17 -> 0 | AC17: =O16 -> 0 | AD17: =Q17 -> 0 | AE17: =J17 -> 0 | AF17: =K17 -> 0 | AG17: =L17 -> 0 | AI17: =T17 -> 0 | AJ17: =U17 -> 0
B18: 11 | L18: 0 | Z18: =D18 -> 0 | AA18: =H18 -> 0 | AB18: =N18 -> 0 | AC18: =O17 -> 0 | AD18: =Q18 -> 0 | AE18: =J18 -> 0 | AF18: =K18 -> 0 | AG18: =L18 -> 0 | AI18: =T18 -> 0 | AJ18: =U18 -> 0
B19: 12 | L19: 0 | Z19: =D19 -> 0 | AA19: =H19 -> 0 | AB19: =N19 -> 0 | AC19: =O18 -> 0 | AD19: =Q19 -> 0 | AE19: =J19 -> 0 | AF19: =K19 -> 0 | AG19: =L19 -> 0 | AI19: =T19 -> 0 | AJ19: =U19 -> 0
B20: 9 | L20: 0 | Z20: =D20 -> 0 | AA20: =H20 -> 0 | AB20: =N20 -> 0 | AC20: =O15 -> 0 | AD20: =Q20 -> 0 | AE20: =J20 -> 0 | AF20: =K20 -> 0 | AG20: =L20 -> 0 | AI20: =T20 -> 0 | AJ20: =U20 -> 0
B21: 10 | L21: 0 | Z21: =D21 -> 0 | AA21: =H21 -> 0 | AB21: =N21 -> 0 | AC21: =O20 -> 0 | AD21: =Q21 -> 0 | AE21: =J21 -> 0 | AF21: =K21 -> 0 | AG21: =L21 -> 0 | AI21: =T21 -> 0 | AJ21: =U21 -> 0
B22: 11 | L22: 0 | Z22: =D22 -> 0 | AA22: =H22 -> 0 | AB22: =N22 -> 0 | AC22: =O21 -> 0 | AD22: =Q22 -> 0 | AE22: =J22 -> 0 | AF22: =K22 -> 0 | AG22: =L22 -> 0 | AI22: =T22 -> 0 | AJ22: =U22 -> 0
B23: 12 | L23: 0 | Z23: =D23 -> 0 | AA23: =H23 -> 0 | AB23: =N23 -> 0 | AC23: =O22 -> 0 | AD23: =Q23 -> 0 | AE23: =J23 -> 0 | AF23: =K23 -> 0 | AG23: =L23 -> 0 | AI23: =T23 -> 0 | AJ23: =U23 -> 0
L25: =SUBTOTAL(9,$L$8:$L$23) -> 0 | M25: =SUBTOTAL(9,$M$8:$M$23) -> 0
D26: Vendor Name | E26: Job Type | F26: Total Billings | G26: Job Name | H26: Vendor Type
F27: =SUMIFS($L$8:$L$23,$D$8:$D$23,$D27,$F$8:$F$23,$E27) -> 0 | G27: =_xlfn.XLOOKUP($D27,$D$8:$D$23,$W$8:$W$23) -> 0 | H27: =_xlfn.XLOOKUP($D27,$D$8:$D$23,$E$8:$E$23) -> 0
F28: =SUMIFS($L$8:$L$23,$D$8:$D$23,$D28,$F$8:$F$23,$E28) -> 0 | G28: =_xlfn.XLOOKUP($D28,$D$8:$D$23,$W$8:$W$23) -> 0 | H28: =_xlfn.XLOOKUP($D28,$D$8:$D$23,$E$8:$E$23) -> 0
F29: =SUMIFS($L$8:$L$23,$D$8:$D$23,$D29,$F$8:$F$23,$E29) -> 0 | G29: =_xlfn.XLOOKUP($D29,$D$8:$D$23,$W$8:$W$23) -> 0 | H29: =_xlfn.XLOOKUP($D29,$D$8:$D$23,$E$8:$E$23) -> 0
F30: =SUMIFS($L$8:$L$23,$D$8:$D$23,$D30,$F$8:$F$23,$E30) -> 0 | G30: =_xlfn.XLOOKUP($D30,$D$8:$D$23,$W$8:$W$23) -> 0 | H30: =_xlfn.XLOOKUP($D30,$D$8:$D$23,$E$8:$E$23) -> 0
F31: =SUMIFS($L$8:$L$23,$D$8:$D$23,$D31,$F$8:$F$23,$E31) -> 0 | G31: =_xlfn.XLOOKUP($D31,$D$8:$D$23,$W$8:$W$23) -> 0 | H31: =_xlfn.XLOOKUP($D31,$D$8:$D$23,$E$8:$E$23) -> 0
F32: =SUMIFS($L$8:$L$23,$D$8:$D$23,$D32,$F$8:$F$23,$E32) -> 0 | G32: =_xlfn.XLOOKUP($D32,$D$8:$D$23,$W$8:$W$23) -> 0 | H32: =_xlfn.XLOOKUP($D32,$D$8:$D$23,$E$8:$E$23) -> 0
F33: =SUMIFS($L$8:$L$23,$D$8:$D$23,$D33,$F$8:$F$23,$E33) -> 0 | G33: =_xlfn.XLOOKUP($D33,$D$8:$D$23,$W$8:$W$23) -> 0 | H33: =_xlfn.XLOOKUP($D33,$D$8:$D$23,$E$8:$E$23) -> 0
F34: =SUM(F27:F33) -> 0
E39: Eligible Total | F39: Qualified Total | G39: Pending Total | H39: DNQ
D40: Agency | E40: =SUMIFS($L$8:$L$23,$E$8:$E$23,$D40) -> 0 | F40: =SUMIFS($L$8:$L$23,$E$8:$E$23,$D40,$C$8:$C$23,"YES") -> 0 | G40: =SUMIFS($L$8:$L$23,$C$8:$C$23,"PENDING",$E$8:$E$23,$D40) -> 0 | H40: =E40-(F40+G40) -> 0
D41: ProdCo | E41: =SUMIFS($L$8:$L$23,$E$8:$E$23,$D41) -> 0 | F41: =SUMIFS($L$8:$L$23,$E$8:$E$23,$D41,$C$8:$C$23,"YES") -> 0 | G41: =SUMIFS($L$8:$L$23,$C$8:$C$23,"PENDING",$E$8:$E$23,$D41) -> 0 | H41: =E41-(F41+G41) -> 0
D42: Sub-ProdCo | E42: =SUMIFS($L$8:$L$23,$E$8:$E$23,$D42) -> 0 | F42: =SUMIFS($L$8:$L$23,$E$8:$E$23,$D42,$C$8:$C$23,"YES") -> 0 | G42: =SUMIFS($L$8:$L$23,$C$8:$C$23,"PENDING",$E$8:$E$23,$D42) -> 0 | H42: =E42-(F42+G42) -> 0
E43: =SUM(E40:E42) -> 0 | F43: =SUM(F40:F42) -> 0 | G43: =SUM(G40:G42) -> 0 | H43: =E43-(F43+G43) -> 0
E47: Agency - Job Number
D49: Production | E49: Job Cost Detail | G49: Amount | H49: 0
G50: Amount Entered | H50: =SUM('Comm Summary (L-L, L-O)'!K20:K40) -> #REF!
G51: Difference | H51: =SUM(H49:H50) -> #REF!
E54: Agency - Job Number
D56: Talent Residuals | E56: Job Cost Detail | G56: Amount | H56: =G40 -> 0
...

Sheet Residency - Callsheet
A1: TPC Commercial Incentives Service
A2: Residency - Callsheet
B7: ITEM_No | C7: XLookUP Name | D7: Document Name | E7: Document Type | F7: Issue_Date | G7: Expiration_Date | H7: Home_Address | I7: City | J7: Zip | K7: State | L7: Diversity | M7: Sex | N7: Notes | O7: Call Sheet Name | P7: Call Sheet Postion

Sheet AICP Bid

Sheet PO Log

Sheet Crew Payroll
B1: Production Tax Incentives PRODUCTION COMPANY CREW PAYROLL
AV2: 1st Shoot Day | AW2: 44831
C3: Project Title: | D3: Kellogg Company "2022 Q3 Eggo Liege TV" | AV3: Last Shoot Day | AW3: 44834
C4: Shoot Date: | D4: 44741 | AL4: FILL-OUT TABLES BELOW THE DATA AFTER ENCODING (TIE-OUTS) | AV4: Covid End Date | AW4: 44896
C5: Work State: | D5: Illinois | U5: 0.062 | V5: 0.0145
BB6: Automated: in case data is not reflected add it to this masterfile | BG6: Don't edit this part; with formulas | BO6: Vac/Hol with | BP6: ER BENEFITS / PH&W
E7: Exclude (Loan Out names) | F7: Use acronym, as will be used in CPA | Y7: DNQ | AC7: DNQ | AL7: INVOICE/ W9 | AP7: PROOF OF PAYMENT | AT7: RESIDENCY | BB7: DIVERSITY
B8: ITEM_No | C8: Qualify | D8: Work_State | E8: Crew_Name | F8: Crew_Position | G8: Position_Category | H8: No_of_Days_Worked | I8: Work Dates | J8: W_Dates_Worked_on_Invoice | K8: Gap_1 | L8: Invoice_Date | M8: PO_No | N8: Invoice_No | O8: Taxable_Wages | P8: Kit Rental | Q8: Mileage Fee | R8: Reimbursement | S8: Rental | T8: Corporate | U8: FICA | V8: Medi | W8: FUI | X8: SUI | Y8: W_C | Z8: PH_W | AA8: Vac_Hol | AB8: Other | AC8: Hand | AD8: Signatory Fee | AE8: Sub_Total | AF8: Non_Eligible | AG8: Total_Eligible | AH8: Automation_Total | AI8: Automation_Check | AJ8: Withholdings Amount | AK8: Withholdings Needed | AL8: Received_Invoice | AM8: Loan Out / 1099 | AN8: Loan_Out_Name | AO8: W9_and_Valid_Date | AP8: Pymt_Method | AQ8: Pymt_No | AR8: Proof_of_Payment | AS8: Payment_Entity | AT8: Document_Type | AU8: Issue_Date | AV8: Expiration_Date | AW8: Residency | AX8: Home_Address | AY8: City | AZ8: Zip | BA8: State | BB8: Diversity | BC8: Sex | BD8: Notes | BF8: Invoice No. | BG8: CPA_Crew_Name | BH8: CPA_Crew_Position | BI8: CPA_Position_Category | BJ8: CPA_Home_Address | BK8: CPA_City | BL8: CPA_Zip | BM8: CPA_No_of_Days_Worked | BN8: CPA_GROSS_WAGES | BO8: CPA_ER_TAXES | BP8: CPA_ER_BENEFITS_PH_W | BQ8: CPA_CPA_TOTAL | BR8: Ineligible1 | BS8: Ineligible2
G9: =_xlfn.XLOOKUP(F9,#REF!,#REF!) -> #REF! | AW9: =IF(C9="NO-OOS","N/A",IF(AT9="Driver's License",IF(AU9>$AW$3,"SOS",IF(AV9>=$AW$3,"Valid",IF(AND(AU9<$AW$3,$AW$4>$AW$3,AU9>AW2),"Covid","Expired"))),IF(AT9="I9",IF(AV9>=$AW$2,"Valid",IF(AND(AT9<$AW$3,$AW$4>$AW$3,AV9>AW2),"Covid","Expired")),IF(AT9="Work Permit",IF(AND(AU9<=$AW$2,(AV9+365)>=$AW$3),"Valid","Expired"),IF(AT9="Missing Residency","Missing",IF(AT9="","","Other")))))) | BN9: =IF($BP$6="GROSS WAGES",(Q9+R9+S9+T9+AA9)-AF9,(Q9+R9+S9+T9)-AF9) -> 0 | BO9: =U9+V9+W9+X9 -> 0 | BP9: =IF($BP$6="ER BENEFITS / PH&W",(Z9+AA9),(Z9)) -> 0 | BQ9: =SUM(BN9:BP9) -> 0 | BR9: =AE9-BQ9 -> 0 | BS9: =BQ9-AE9+Y9+AC9+AF9 -> 0
B10: 1 | G10: =_xlfn.XLOOKUP(F10,#REF!,#REF!) -> #REF! | O10: 0 | P10: 0 | Q10: 0 | R10: 0 | S10: 0 | T10: 0 | U10: 0 | V10: 0 | W10: 0 | X10: 0 | Y10: 0 | Z10: 0 | AA10: 0 | AB10: 0 | AC10: 0 | AD10: 0 | AE10: =SUM(O10:AC10) -> 0 | AF10: 0 | AG10: =AE10-AF10 -> 0 | AH10: 0 | AI10: =AE10-AG10 -> 0 | AW10: =IF(C10="NO-OOS","N/A",IF(AT10="Driver's License",IF(AU10>$AW$3,"SOS",IF(AV10>=$AW$3,"Valid",IF(AND(AU10<$AW$3,$AW$4>$AW$3,AU10>AW3),"Covid","Expired"))),IF(AT10="I9",IF(AV10>=$AW$2,"Valid",IF(AND(AT10<$AW$3,$AW$4>$AW$3,AV10>AW3),"Covid","Expired")),IF(AT10="Work Permit",IF(AND(AU10<=$AW$2,(AV10+365)>=$AW$3),"Valid","Expired"),IF(AT10="Missing Residency","Missing",IF(AT10="","","Other")))))) | BF10: =N10 -> 0 | BG10: =E10 -> 0 | BH10: =F10 -> 0 | BI10: =G10 -> #REF! | BJ10: =AX10 -> 0 | BK10: =AY10 -> 0 | BL10: =AZ10 -> 0 | BM10: =H10 -> 0 | BN10: =IF($BP$6="GROSS WAGES",(O10+P10+Q10+R10+S10+T10+AA10)-AF10,(O10+P10+Q10+R10+S10+T10)-AF10) -> 0 | BO10: =U10+V10+W10+X10 -> 0 | BP10: =IF($BP$6="ER BENEFITS / PH&W",(Z10+AA10),(Z10)) -> 0 | BQ10: =SUM(BN10:BP10) -> 0 | BR10: =AE10-BQ10 -> 0 | BS10: =BQ10-AE10+Y10+AC10+AF10 -> 0
B11: 2 | G11: =_xlfn.XLOOKUP(F11,#REF!,#REF!) -> #REF! | O11: 0 | P11: 0 | Q11: 0 | R11: 0 | S11: 0 | T11: 0 | U11: 0 | V11: 0 | W11: 0 | X11: 0 | Y11: 0 | Z11: 0 | AA11: 0 | AB11: 0 | AC11: 0 | AD11: 0 | AE11: =SUM(Q11:AC11) -> 0 | AF11: 0 | AG11: =AE11-AF11 -> 0 | AH11: 0 | AI11: =AE11-AG11 -> 0 | AW11: =IF(C11="NO-OOS","N/A",IF(AT11="Driver's License",IF(AU11>$AW$3,"SOS",IF(AV11>=$AW$3,"Valid",IF(AND(AU11<$AW$3,$AW$4>$AW$3,AU11>AW4),"Covid","Expired"))),IF(AT11="I9",IF(AV11>=$AW$2,"Valid",IF(AND(AT11<$AW$3,$AW$4>$AW$3,AV11>AW4),"Covid","Expired")),IF(AT11="Work Permit",IF(AND(AU11<=$AW$2,(AV11+365)>=$AW$3),"Valid","Expired"),IF(AT11="Missing Residency","Missing",IF(AT11="","","Other")))))) | BF11: =N11 -> 0 | BG11: =E11 -> 0 | BH11: =F11 -> 0 | BI11: =G11 -> #REF! | BJ11: =AX11 -> 0 | BK11: =AY11 -> 0 | BL11: =AZ11 -> 0 | BM11: =H11 -> 0 | BN11: =IF($BP$6="GROSS WAGES",(O11+P11+Q11+R11+S11+T11+AA11)-AF11,(O11+P11+Q11+R11+S11+T11)-AF11) -> 0 | BO11: =U11+V11+W11+X11 -> 0 | BP11: =IF($BP$6="ER BENEFITS / PH&W",(Z11+AA11),(Z11)) -> 0 | BQ11: =SUM(BN11:BP11) -> 0 | BR11: =AE11-BQ11 -> 0 | BS11: =BQ11-AE11+Y11+AC11+AF11 -> 0
B12: 3 | G12: =_xlfn.XLOOKUP(F12,#REF!,#REF!) -> #REF! | O12: 0 | P12: 0 | Q12: 0 | R12: 0 | S12: 0 | T12: 0 | U12: 0 | V12: 0 | W12: 0 | X12: 0 | Y12: 0 | Z12: 0 | AA12: 0 | AB12: 0 | AC12: 0 | AD12: 0 | AE12: =SUM(Q12:AC12) -> 0 | AF12: 0 | AG12: =AE12-AF12 -> 0 | AH12: 0 | AI12: =AE12-AG12 -> 0 | AW12: =IF(C12="NO-OOS","N/A",IF(AT12="Driver's License",IF(AU12>$AW$3,"SOS",IF(AV12>=$AW$3,"Valid",IF(AND(AU12<$AW$3,$AW$4>$AW$3,AU12>AW5),"Covid","Expired"))),IF(AT12="I9",IF(AV12>=$AW$2,"Valid",IF(AND(AT12<$AW$3,$AW$4>$AW$3,AV12>AW5),"Covid","Expired")),IF(AT12="Work Permit",IF(AND(AU12<=$AW$2,(AV12+365)>=$AW$3),"Valid","Expired"),IF(AT12="Missing Residency","Missing",IF(AT12="","","Other")))))) | BF12: =N12 -> 0 | BG12: =E12 -> 0 | BH12: =F12 -> 0 | BI12: =G12 -> #REF! | BJ12: =AX12 -> 0 | BK12: =AY12 -> 0 | BL12: =AZ12 -> 0 | BM12: =H12 -> 0 | BN12: =IF($BP$6="GROSS WAGES",(O12+P12+Q12+R12+S12+T12+AA12)-AF12,(O12+P12+Q12+R12+S12+T12)-AF12) -> 0 | BO12: =U12+V12+W12+X12 -> 0 | BP12: =IF($BP$6="ER BENEFITS / PH&W",(Z12+AA12),(Z12)) -> 0 | BQ12: =SUM(BN12:BP12) -> 0 | BR12: =AE12-BQ12 -> 0 | BS12: =BQ12-AE12+Y12+AC12+AF12 -> 0
B13: 4 | G13: =_xlfn.XLOOKUP(F13,#REF!,#REF!) -> #REF! | O13: 0 | P13: 0 | Q13: 0 | R13: 0 | S13: 0 | T13: 0 | U13: 0 | V13: 0 | W13: 0 | X13: 0 | Y13: 0 | Z13: 0 | AA13: 0 | AB13: 0 | AC13: 0 | AD13: 0 | AE13: =SUM(Q13:AC13) -> 0 | AF13: 0 | AG13: =AE13-AF13 -> 0 | AH13: 0 | AI13: =AE13-AG13 -> 0 | AW13: =IF(C13="NO-OOS","N/A",IF(AT13="Driver's License",IF(AU13>$AW$3,"SOS",IF(AV13>=$AW$3,"Valid",IF(AND(AU13<$AW$3,$AW$4>$AW$3,AU13>AW6),"Covid","Expired"))),IF(AT13="I9",IF(AV13>=$AW$2,"Valid",IF(AND(AT13<$AW$3,$AW$4>$AW$3,AV13>AW6),"Covid","Expired")),IF(AT13="Work Permit",IF(AND(AU13<=$AW$2,(AV13+365)>=$AW$3),"Valid","Expired"),IF(AT13="Missing Residency","Missing",IF(AT13="","","Other")))))) | BF13: =N13 -> 0 | BG13: =E13 -> 0 | BH13: =F13 -> 0 | BI13: =G13 -> #REF! | BJ13: =AX13 -> 0 | BK13: =AY13 -> 0 | BL13: =AZ13 -> 0 | BM13: =H13 -> 0 | BN13: =IF($BP$6="GROSS WAGES",(O13+P13+Q13+R13+S13+T13+AA13)-AF13,(O13+P13+Q13+R13+S13+T13)-AF13) -> 0 | BO13: =U13+V13+W13+X13 -> 0 | BP13: =IF($BP$6="ER BENEFITS / PH&W",(Z13+AA13),(Z13)) -> 0 | BQ13: =SUM(BN13:BP13) -> 0 | BR13: =AE13-BQ13 -> 0 | BS13: =BQ13-AE13+Y13+AC13+AF13 -> 0
B14: 5 | G14: =_xlfn.XLOOKUP(F14,#REF!,#REF!) -> #REF! | O14: 0 | P14: 0 | Q14: 0 | R14: 0 | S14: 0 | T14: 0 | U14: 0 | V14: 0 | W14: 0 | X14: 0 | Y14: 0 | Z14: 0 | AA14: 0 | AB14: 0 | AC14: 0 | AD14: 0 | AE14: =SUM(Q14:AC14) -> 0 | AF14: 0 | AG14: =AE14-AF14 -> 0 | AH14: 0 | AI14: =AE14-AG14 -> 0 | AW14: =IF(C14="NO-OOS","N/A",IF(AT14="Driver's License",IF(AU14>$AW$3,"SOS",IF(AV14>=$AW$3,"Valid",IF(AND(AU14<$AW$3,$AW$4>$AW$3,AU14>AW7),"Covid","Expired"))),IF(AT14="I9",IF(AV14>=$AW$2,"Valid",IF(AND(AT14<$AW$3,$AW$4>$AW$3,AV14>AW7),"Covid","Expired")),IF(AT14="Work Permit",IF(AND(AU14<=$AW$2,(AV14+365)>=$AW$3),"Valid","Expired"),IF(AT14="Missing Residency","Missing",IF(AT14="","","Other")))))) | BF14: =N14 -> 0 | BG14: =E14 -> 0 | BH14: =F14 -> 0 | BI14: =G14 -> #REF! | BJ14: =AX14 -> 0 | BK14: =AY14 -> 0 | BL14: =AZ14 -> 0 | BM14: =H14 -> 0 | BN14: =IF($BP$6="GROSS WAGES",(O14+P14+Q14+R14+S14+T14+AA14)-AF14,(O14+P14+Q14+R14+S14+T14)-AF14) -> 0 | BO14: =U14+V14+W14+X14 -> 0 | BP14: =IF($BP$6="ER BENEFITS / PH&W",(Z14+AA14),(Z14)) -> 0 | BQ14: =SUM(BN14:BP14) -> 0 | BR14: =AE14-BQ14 -> 0 | BS14: =BQ14-AE14+Y14+AC14+AF14 -> 0
B15: 6 | G15: =_xlfn.XLOOKUP(F15,#REF!,#REF!) -> #REF! | O15: 0 | P15: 0 | Q15: 0 | R15: 0 | S15: 0 | T15: 0 | U15: 0 | V15: 0 | W15: 0 | X15: 0 | Y15: 0 | Z15: 0 | AA15: 0 | AB15: 0 | AC15: 0 | AD15: 0 | AE15: =SUM(Q15:AC15) -> 0 | AF15: 0 | AG15: =AE15-AF15 -> 0 | AH15: 0 | AI15: =AE15-AG15 -> 0 | AW15: =IF(C15="NO-OOS","N/A",IF(AT15="Driver's License",IF(AU15>$AW$3,"SOS",IF(AV15>=$AW$3,"Valid",IF(AND(AU15<$AW$3,$AW$4>$AW$3,AU15>AW8),"Covid","Expired"))),IF(AT15="I9",IF(AV15>=$AW$2,"Valid",IF(AND(AT15<$AW$3,$AW$4>$AW$3,AV15>AW8),"Covid","Expired")),IF(AT15="Work Permit",IF(AND(AU15<=$AW$2,(AV15+365)>=$AW$3),"Valid","Expired"),IF(AT15="Missing Residency","Missing",IF(AT15="","","Other")))))) | BF15: =N15 -> 0 | BG15: =E15 -> 0 | BH15: =F15 -> 0 | BI15: =G15 -> #REF! | BJ15: =AX15 -> 0 | BK15: =AY15 -> 0 | BL15: =AZ15 -> 0 | BM15: =H15 -> 0 | BN15: =IF($BP$6="GROSS WAGES",(O15+P15+Q15+R15+S15+T15+AA15)-AF15,(O15+P15+Q15+R15+S15+T15)-AF15) -> 0 | BO15: =U15+V15+W15+X15 -> 0 | BP15: =IF($BP$6="ER BENEFITS / PH&W",(Z15+AA15),(Z15)) -> 0 | BQ15: =SUM(BN15:BP15) -> 0 | BR15: =AE15-BQ15 -> 0 | BS15: =BQ15-AE15+Y15+AC15+AF15 -> 0
B16: 7 | G16: =_xlfn.XLOOKUP(F16,#REF!,#REF!) -> #REF! | O16: 0 | P16: 0 | Q16: 0 | R16: 0 | S16: 0 | T16: 0 | U16: 0 | V16: 0 | W16: 0 | X16: 0 | Y16: 0 | Z16: 0 | AA16: 0 | AB16: 0 | AC16: 0 | AD16: 0 | AE16: =SUM(Q16:AC16) -> 0 | AF16: 0 | AG16: =AE16-AF16 -> 0 | AH16: 0 | AI16: =AE16-AG16 -> 0 | AW16: =IF(C16="NO-OOS","N/A",IF(AT16="Driver's License",IF(AU16>$AW$3,"SOS",IF(AV16>=$AW$3,"Valid",IF(AND(AU16<$AW$3,$AW$4>$AW$3,AU16>AW9),"Covid","Expired"))),IF(AT16="I9",IF(AV16>=$AW$2,"Valid",IF(AND(AT16<$AW$3,$AW$4>$AW$3,AV16>AW9),"Covid","Expired")),IF(AT16="Work Permit",IF(AND(AU16<=$AW$2,(AV16+365)>=$AW$3),"Valid","Expired"),IF(AT16="Missing Residency","Missing",IF(AT16="","","Other")))))) | BF16: =N16 -> 0 | BG16: =E16 -> 0 | BH16: =F16 -> 0 | BI16: =G16 -> #REF! | BJ16: =AX16 -> 0 | BK16: =AY16 -> 0 | BL16: =AZ16 -> 0 | BM16: =H16 -> 0 | BN16: =IF($BP$6="GROSS WAGES",(O16+P16+Q16+R16+S16+T16+AA16)-AF16,(O16+P16+Q16+R16+S16+T16)-AF16) -> 0 | BO16: =U16+V16+W16+X16 -> 0 | BP16: =IF($BP$6="ER BENEFITS / PH&W",(Z16+AA16),(Z16)) -> 0 | BQ16: =SUM(BN16:BP16) -> 0 | BR16: =AE16-BQ16 -> 0 | BS16: =BQ16-AE16+Y16+AC16+AF16 -> 0
B17: 8 | G17: =_xlfn.XLOOKUP(F17,#REF!,#REF!) -> #REF! | O17: 0 | P17: 0 | Q17: 0 | R17: 0 | S17: 0 | T17: 0 | U17: 0 | V17: 0 | W17: 0 | X17: 0 | Y17: 0 | Z17: 0 | AA17: 0 | AB17: 0 | AC17: 0 | AD17: 0 | AE17: =SUM(Q17:AC17) -> 0 | AF17: 0 | AG17: =AE17-AF17 -> 0 | AH17: 0 | AI17: =AE17-AG17 -> 0 | AW17: =IF(C17="NO-OOS","N/A",IF(AT17="Driver's License",IF(AU17>$AW$3,"SOS",IF(AV17>=$AW$3,"Valid",IF(AND(AU17<$AW$3,$AW$4>$AW$3,AU17>AW10),"Covid","Expired"))),IF(AT17="I9",IF(AV17>=$AW$2,"Valid",IF(AND(AT17<$AW$3,$AW$4>$AW$3,AV17>AW10),"Covid","Expired")),IF(AT17="Work Permit",IF(AND(AU17<=$AW$2,(AV17+365)>=$AW$3),"Valid","Expired"),IF(AT17="Missing Residency","Missing",IF(AT17="","","Other")))))) | BF17: =N17 -> 0 | BG17: =E17 -> 0 | BH17: =F17 -> 0 | BI17: =G17 -> #REF! | BJ17: =AX17 -> 0 | BK17: =AY17 -> 0 | BL17: =AZ17 -> 0 | BM17: =H17 -> 0 | BN17: =IF($BP$6="GROSS WAGES",(O17+P17+Q17+R17+S17+T17+AA17)-AF17,(O17+P17+Q17+R17+S17+T17)-AF17) -> 0 | BO17: =U17+V17+W17+X17 -> 0 | BP17: =IF($BP$6="ER BENEFITS / PH&W",(Z17+AA17),(Z17)) -> 0 | BQ17: =SUM(BN17:BP17) -> 0 | BR17: =AE17-BQ17 -> 0 | BS17: =BQ17-AE17+Y17+AC17+AF17 -> 0
B18: 9 | G18: =_xlfn.XLOOKUP(F18,#REF!,#REF!) -> #REF! | O18: 0 | P18: 0 | Q18: 0 | R18: 0 | S18: 0 | T18: 0 | U18: 0 | V18: 0 | W18: 0 | X18: 0 | Y18: 0 | Z18: 0 | AA18: 0 | AB18: 0 | AC18: 0 | AD18: 0 | AE18: =SUM(Q18:AC18) -> 0 | AF18: 0 | AG18: =AE18-AF18 -> 0 | AH18: 0 | AI18: =AE18-AG18 -> 0 | AW18: =IF(C18="NO-OOS","N/A",IF(AT18="Driver's License",IF(AU18>$AW$3,"SOS",IF(AV18>=$AW$3,"Valid",IF(AND(AU18<$AW$3,$AW$4>$AW$3,AU18>AW11),"Covid","Expired"))),IF(AT18="I9",IF(AV18>=$AW$2,"Valid",IF(AND(AT18<$AW$3,$AW$4>$AW$3,AV18>AW11),"Covid","Expired")),IF(AT18="Work Permit",IF(AND(AU18<=$AW$2,(AV18+365)>=$AW$3),"Valid","Expired"),IF(AT18="Missing Residency","Missing",IF(AT18="","","Other")))))) | BF18: =N18 -> 0 | BG18: =E18 -> 0 | BH18: =F18 -> 0 | BI18: =G18 -> #REF! | BJ18: =AX18 -> 0 | BK18: =AY18 -> 0 | BL18: =AZ18 -> 0 | BM18: =H18 -> 0 | BN18: =IF($BP$6="GROSS WAGES",(O18+P18+Q18+R18+S18+T18+AA18)-AF18,(O18+P18+Q18+R18+S18+T18)-AF18) -> 0 | BO18: =U18+V18+W18+X18 -> 0 | BP18: =IF($BP$6="ER BENEFITS / PH&W",(Z18+AA18),(Z18)) -> 0 | BQ18: =SUM(BN18:BP18) -> 0 | BR18: =AE18-BQ18 -> 0 | BS18: =BQ18-AE18+Y18+AC18+AF18 -> 0
B19: 10 | G19: =_xlfn.XLOOKUP(F19,#REF!,#REF!) -> #REF! | O19: 0 | P19: 0 | Q19: 0 | R19: 0 | S19: 0 | T19: 0 | U19: 0 | V19: 0 | W19: 0 | X19: 0 | Y19: 0 | Z19: 0 | AA19: 0 | AB19: 0 | AC19: 0 | AD19: 0 | AE19: =SUM(Q19:AC19) -> 0 | AF19: 0 | AG19: =AE19-AF19 -> 0 | AH19: 0 | AI19: =AE19-AG19 -> 0 | AW19: =IF(C19="NO-OOS","N/A",IF(AT19="Driver's License",IF(AU19>$AW$3,"SOS",IF(AV19>=$AW$3,"Valid",IF(AND(AU19<$AW$3,$AW$4>$AW$3,AU19>AW12),"Covid","Expired"))),IF(AT19="I9",IF(AV19>=$AW$2,"Valid",IF(AND(AT19<$AW$3,$AW$4>$AW$3,AV19>AW12),"Covid","Expired")),IF(AT19="Work Permit",IF(AND(AU19<=$AW$2,(AV19+365)>=$AW$3),"Valid","Expired"),IF(AT19="Missing Residency","Missing",IF(AT19="","","Other")))))) | BF19: =N19 -> 0 | BG19: =E19 -> 0 | BH19: =F19 -> 0 | BI19: =G19 -> #REF! | BJ19: =AX19 -> 0 | BK19: =AY19 -> 0 | BL19: =AZ19 -> 0 | BM19: =H19 -> 0 | BN19: =IF($BP$6="GROSS WAGES",(O19+P19+Q19+R19+S19+T19+AA19)-AF19,(O19+P19+Q19+R19+S19+T19)-AF19) -> 0 | BO19: =U19+V19+W19+X19 -> 0 | BP19: =IF($BP$6="ER BENEFITS / PH&W",(Z19+AA19),(Z19)) -> 0 | BQ19: =SUM(BN19:BP19) -> 0 | BR19: =AE19-BQ19 -> 0 | BS19: =BQ19-AE19+Y19+AC19+AF19 -> 0
B20: 11 | G20: =_xlfn.XLOOKUP(F20,#REF!,#REF!) -> #REF! | O20: 0 | P20: 0 | Q20: 0 | R20: 0 | S20: 0 | T20: 0 | U20: 0 | V20: 0 | W20: 0 | X20: 0 | Y20: 0 | Z20: 0 | AA20: 0 | AB20: 0 | AC20: 0 | AD20: 0 | AE20: =SUM(Q20:AC20) -> 0 | AF20: 0 | AG20: =AE20-AF20 -> 0 | AH20: 0 | AI20: =AE20-AG20 -> 0 | AW20: =IF(C20="NO-OOS","N/A",IF(AT20="Driver's License",IF(AU20>$AW$3,"SOS",IF(AV20>=$AW$3,"Valid",IF(AND(AU20<$AW$3,$AW$4>$AW$3,AU20>AW13),"Covid","Expired"))),IF(AT20="I9",IF(AV20>=$AW$2,"Valid",IF(AND(AT20<$AW$3,$AW$4>$AW$3,AV20>AW13),"Covid","Expired")),IF(AT20="Work Permit",IF(AND(AU20<=$AW$2,(AV20+365)>=$AW$3),"Valid","Expired"),IF(AT20="Missing Residency","Missing",IF(AT20="","","Other")))))) | BF20: =N20 -> 0 | BG20: =E20 -> 0 | BH20: =F20 -> 0 | BI20: =G20 -> #REF! | BJ20: =AX20 -> 0 | BK20: =AY20 -> 0 | BL20: =AZ20 -> 0 | BM20: =H20 -> 0 | BN20: =IF($BP$6="GROSS WAGES",(O20+P20+Q20+R20+S20+T20+AA20)-AF20,(O20+P20+Q20+R20+S20+T20)-AF20) -> 0 | BO20: =U20+V20+W20+X20 -> 0 | BP20: =IF($BP$6="ER BENEFITS / PH&W",(Z20+AA20),(Z20)) -> 0 | BQ20: =SUM(BN20:BP20) -> 0 | BR20: =AE20-BQ20 -> 0 | BS20: =BQ20-AE20+Y20+AC20+AF20 -> 0
B21: 12 | G21: =_xlfn.XLOOKUP(F21,#REF!,#REF!) -> #REF! | O21: 0 | P21: 0 | Q21: 0 | R21: 0 | S21: 0 | T21: 0 | U21: 0 | V21: 0 | W21: 0 | X21: 0 | Y21: 0 | Z21: 0 | AA21: 0 | AB21: 0 | AC21: 0 | AD21: 0 | AE21: =SUM(Q21:AC21) -> 0 | AF21: 0 | AG21: =AE21-AF21 -> 0 | AH21: 0 | AI21: =AE21-AG21 -> 0 | AW21: =IF(C21="NO-OOS","N/A",IF(AT21="Driver's License",IF(AU21>$AW$3,"SOS",IF(AV21>=$AW$3,"Valid",IF(AND(AU21<$AW$3,$AW$4>$AW$3,AU21>AW14),"Covid","Expired"))),IF(AT21="I9",IF(AV21>=$AW$2,"Valid",IF(AND(AT21<$AW$3,$AW$4>$AW$3,AV21>AW14),"Covid","Expired")),IF(AT21="Work Permit",IF(AND(AU21<=$AW$2,(AV21+365)>=$AW$3),"Valid","Expired"),IF(AT21="Missing Residency","Missing",IF(AT21="","","Other")))))) | BF21: =N21 -> 0 | BG21: =E21 -> 0 | BH21: =F21 -> 0 | BI21: =G21 -> #REF! | BJ21: =AX21 -> 0 | BK21: =AY21 -> 0 | BL21: =AZ21 -> 0 | BM21: =H21 -> 0 | BN21: =IF($BP$6="GROSS WAGES",(O21+P21+Q21+R21+S21+T21+AA21)-AF21,(O21+P21+Q21+R21+S21+T21)-AF21) -> 0 | BO21: =U21+V21+W21+X21 -> 0 | BP21: =IF($BP$6="ER BENEFITS / PH&W",(Z21+AA21),(Z21)) -> 0 | BQ21: =SUM(BN21:BP21) -> 0 | BR21: =AE21-BQ21 -> 0 | BS21: =BQ21-AE21+Y21+AC21+AF21 -> 0
B22: 13 | G22: =_xlfn.XLOOKUP(F22,#REF!,#REF!) -> #REF! | O22: 0 | P22: 0 | Q22: 0 | R22: 0 | S22: 0 | T22: 0 | U22: 0 | V22: 0 | W22: 0 | X22: 0 | Y22: 0 | Z22: 0 | AA22: 0 | AB22: 0 | AC22: 0 | AD22: 0 | AE22: =SUM(Q22:AC22) -> 0 | AF22: 0 | AG22: =AE22-AF22 -> 0 | AH22: 0 | AI22: =AE22-AG22 -> 0 | AW22: =IF(C22="NO-OOS","N/A",IF(AT22="Driver's License",IF(AU22>$AW$3,"SOS",IF(AV22>=$AW$3,"Valid",IF(AND(AU22<$AW$3,$AW$4>$AW$3,AU22>AW15),"Covid","Expired"))),IF(AT22="I9",IF(AV22>=$AW$2,"Valid",IF(AND(AT22<$AW$3,$AW$4>$AW$3,AV22>AW15),"Covid","Expired")),IF(AT22="Work Permit",IF(AND(AU22<=$AW$2,(AV22+365)>=$AW$3),"Valid","Expired"),IF(AT22="Missing Residency","Missing",IF(AT22="","","Other")))))) | BF22: =N22 -> 0 | BG22: =E22 -> 0 | BH22: =F22 -> 0 | BI22: =G22 -> #REF! | BJ22: =AX22 -> 0 | BK22: =AY22 -> 0 | BL22: =AZ22 -> 0 | BM22: =H22 -> 0 | BN22: =IF($BP$6="GROSS WAGES",(O22+P22+Q22+R22+S22+T22+AA22)-AF22,(O22+P22+Q22+R22+S22+T22)-AF22) -> 0 | BO22: =U22+V22+W22+X22 -> 0 | BP22: =IF($BP$6="ER BENEFITS / PH&W",(Z22+AA22),(Z22)) -> 0 | BQ22: =SUM(BN22:BP22) -> 0 | BR22: =AE22-BQ22 -> 0 | BS22: =BQ22-AE22+Y22+AC22+AF22 -> 0
... B39: 30 | G39: =_xlfn.XLOOKUP(F39,#REF!,#REF!) -> #REF! | O39: 0 | P39: 0 | Q39: 0 | R39: 0 | S39: 0 | T39: 0 | U39: 0 | V39: 0 | W39: 0 | X39: 0 | Y39: 0 | Z39: 0 | AA39: 0 | AB39: 0 | AC39: 0 | AD39: 0 | AE39: =SUM(Q39:AC39) -> 0 | AF39: 0 | AG39: =AE39-AF39 -> 0 | AH39: 0 | AI39: =AE39-AG39 -> 0 | AW39: =IF(C39="NO-OOS","N/A",IF(AT39="Driver's License",IF(AU39>$AW$3,"SOS",IF(AV39>=$AW$3,"Valid",IF(AND(AU39<$AW$3,$AW$4>$AW$3,AU39>AW32),"Covid","Expired"))),IF(AT39="I9",IF(AV39>=$AW$2,"Valid",IF(AND(AT39<$AW$3,$AW$4>$AW$3,AV39>AW32),"Covid","Expired")),IF(AT39="Work Permit",IF(AND(AU39<=$AW$2,(AV39+365)>=$AW$3),"Valid","Expired"),IF(AT39="Missing Residency","Missing",IF(AT39="","","Other")))))) | BF39: =N39 -> 0 | BG39: =E39 -> 0 | BH39: =F39 -> 0 | BI39: =G39 -> #REF! | BJ39: =AX39 -> 0 | BK39: =AY39 -> 0 | BL39: =AZ39 -> 0 | BM39: =H39 -> 0 | BN39: =IF($BP$6="GROSS WAGES",(O39+P39+Q39+R39+S39+T39+AA39)-AF39,(O39+P39+Q39+R39+S39+T39)-AF39) -> 0 | BO39: =U39+V39+W39+X39 -> 0 | BP39: =IF($BP$6="ER BENEFITS / PH&W",(Z39+AA39),(Z39)) -> 0 | BQ39: =SUM(BN39:BP39) -> 0 | BR39: =AE39-BQ39 -> 0 | BS39: =BQ39-AE39+Y39+AC39+AF39 -> 0
O40: 0 | P40: 0 | Q40: 0 | R40: 0 | S40: 0 | T40: 0 | U40: 0 | V40: 0 | W40: 0 | X40: 0 | Y40: 0 | AI40: =AE40-AG40 -> 0 | AW40: =IF(C40="NO-OOS","N/A",IF(AT40="Driver's License",IF(AU40>$AW$3,"SOS",IF(AV40>=$AW$3,"Valid",IF(AND(AU40<$AW$3,$AW$4>$AW$3,AU40>43831),"Covid","Expired"))),IF(AT40="I9",IF(AU40>=$AW$3,"Valid",IF(AND(AT40<$AW$3,$AW$4>$AW$3,AU40>43831),"Covid","Expired")),IF(AT40="Work Permit",IF(AND(AU40<=$AW$2,(AV40+365)>=$AW$3),"Valid","Expired"),IF(AT40="Missing Residency","Missing",IF(AT40="","","Other")))))) | BF40: =N40 -> 0 | BG40: =E40 -> 0 | BH40: =F40 -> 0 | BI40: =G40 -> 0 | BJ40: =AX40 -> 0 | BK40: =AY40 -> 0 | BL40: =AZ40 -> 0 | BM40: =H40 -> 0 | BN40: =IF($BP$6="GROSS WAGES",(O40+P40+Q40+R40+S40+T40+AA40)-AF40,(O40+P40+Q40+R40+S40+T40)-AF40) -> 0 | BO40: =U40+V40+W40+X40 -> 0 | BP40: =IF($BP$6="ER BENEFITS / PH&W",(Z40+AA40),(Z40)) -> 0 | BQ40: =SUM(BN40:BP40) -> 0 | BR40: =AE40-BQ40 -> 0 | BS40: =BQ40-AE40+Y40+AC40+AF40 -> 0
O41: 0 | P41: 0 | Q41: 0 | R41: 0 | S41: 0 | T41: 0 | U41: 0 | V41: 0 | W41: 0 | X41: 0 | AI41: =AE41-AG41 -> 0 | AW41: =IF(C41="NO-OOS","N/A",IF(AT41="Driver's License",IF(AU41>$AW$3,"SOS",IF(AV41>=$AW$4,"Valid",IF(AND(AV41<$AW$4,$AW$5>$AW$4,AV41>43831),"Covid","Expired"))),IF(AT41="I9",IF(AV41>=$AW$4,"Valid",IF(AND(AV41<$AW$4,$AW$5>$AW$4,AV41>43831),"Covid","Expired")),IF(AT41="Work Permit",IF(AND(AU41<=$AW$3,(AU41+365)>=$AW$4),"Valid","Expired"),IF(AT41="Missing Residency","Missing",IF(AT41="","","Other")))))) | BF41: =N41 -> 0 | BG41: =E41 -> 0 | BH41: =F41 -> 0 | BI41: =G41 -> 0 | BJ41: =AX41 -> 0 | BK41: =AY41 -> 0 | BL41: =AZ41 -> 0 | BM41: =H41 -> 0 | BN41: =IF($BP$6="GROSS WAGES",(O41+P41+Q41+R41+S41+T41+AA41)-AF41,(O41+P41+Q41+R41+S41+T41)-AF41) -> 0 | BO41: =U41+V41+W41+X41 -> 0 | BP41: =IF($BP$6="ER BENEFITS / PH&W",(Z41+AA41),(Z41)) -> 0 | BQ41: =SUM(BN41:BP41) -> 0 | BR41: =AE41-BQ41 -> 0 | BS41: =BQ41-AE41+Y41+AC41+AF41 -> 0
O42: =SUBTOTAL(9,O9:O41) -> 0 | P42: =SUBTOTAL(9,P9:P41) -> 0 | Q42: =SUBTOTAL(9,Q9:Q41) -> 0 | R42: =SUBTOTAL(9,R9:R41) -> 0 | S42: =SUBTOTAL(9,S9:S41) -> 0 | T42: =SUBTOTAL(9,T9:T41) -> 0 | U42: =SUBTOTAL(9,U9:U41) -> 0 | V42: =SUBTOTAL(9,V9:V41) -> 0 | ... AG42: =SUBTOTAL(9,AG9:AG41) -> 0 | BN42: =SUBTOTAL(9,BN9:BN41) -> 0 | BO42: =SUBTOTAL(9,BO9:BO41) -> 0 | BP42: =SUBTOTAL(9,BP9:BP41) -> 0 | BQ42: =SUBTOTAL(9,BQ9:BQ41) -> 0 | BR42: =SUM(BR9:BR41) -> 0 | BS42: =BQ42-AE42+Y42+AC42+AF42 -> 0
O45: =SUM(O9:O41) -> 0 | P45: =SUM(P9:P41) -> 0 | Q45: =SUM(Q9:Q41) -> 0 | R45: =SUM(R9:R41) -> 0 | S45: =SUM(S9:S41) -> 0 | T45: =SUM(T9:T41) -> 0 | U45: =SUM(U9:U41) -> 0 | V45: =SUM(V9:V41) -> 0 | ... AG45: =SUM(AG9:AG41) -> 0 | BN45: =SUM(BN9:BN41) -> 0 | BO45: =SUM(BO9:BO41) -> 0 | BP45: =SUM(BP9:BP41) -> 0 | BQ45: =SUM(BQ9:BQ41) -> 0 | BR45: =SUM(BR9:BR41) -> 0
R51: Number of YES-OOS | S51: =COUNTIFS($C$9:$C$41,"YES-OOS") -> 0 | W51: ELIGIBLE TOTAL
U52: PENDING | V52: NO-OOS | W52: NO-IL | X52: YES-OOS | Y52: YES
R53: Total Eligible | S53: =(Y53)-S57 -> 0 | U53: =SUMIF($C$9:$C$41,U52,$BQ$9:$BQ$41) -> 0 | V53: =SUMIF($C$9:$C$41,V52,$BQ$9:$BQ$41) -> 0 | W53: =SUMIF($C$9:$C$41,W52,$BQ$9:$BQ$41) -> 0 | X53: =SUMIF($C$9:$C$41,X52,$BQ$9:$BQ$41) -> 0 | Y53: =SUMIF($C$9:$C$41,Y52,$BQ$9:$BQ$41) -> 0 | Z53: =SUM(U53:Y53) -> 0
R54: Two OOS Crew | S54: =X53 -> 0 | Z54: =Z53-BQ45 -> 0
R55: Pending | S55: =U53 -> 0
R56: Total Ineligible | S56: =V53+W53+V58+W58+Y58+X58+U58 -> 0 | W56: INELIGIBLE TOTAL
R57: PAs | S57: =SUMIF(AS9:AS41,"Elite CIS",AE9:AE41) -> 0 | U57: PENDING | V57: NO-OOS | W57: NO-IL | X57: YES-OOS | Y57: YES
R58: Total Expenses | S58: =SUM(S53:S57) -> 0 | U58: =SUMIF($C$9:$C$41,U57,$BR$9:$BR$41) -> 0 | V58: =SUMIF($C$9:$C$41,V57,$BR$9:$BR$41) -> 0 | W58: =SUMIF($C$9:$C$41,W57,$BR$9:$BR$41) -> 0 | X58: =SUMIF($C$9:$C$41,X57,$BR$9:$BR$41) -> 0 | Y58: =SUMIF($C$9:$C$41,Y57,$BR$9:$BR$41) -> 0 | Z58: =SUM(U58:Y58) -> 0
S59: =S58-AE45 -> 0 | Z59: =Z58-BR45 -> 0
R62: Payroll & Crew Invoice No. | S62: Invoice Amount | T62: Qualified Amount | U62: Pending | V62: Ineligible Amount | W62: Gross | X62: ER Taxes | Y62: Benefits (P, H & W) | Z62: Total Qualified
R63: 1 | S63: =SUMIF($N$9:$N$41,R63,$AE$9:$AE$41) -> 0 | T63: =SUMIFS($BQ$9:$BQ$41,$N$9:$N$41,R63,$C$9:$C$41,"YES")+SUMIFS($BQ$9:$BQ$41,$N$9:$N$41,R63,$C$9:$C$41,"YES-OOS") -> 0 | U63: =SUMIFS($BQ$9:$BQ$41,$N$9:$N$41,R63,$C$9:$C$41,"PENDING") -> 0 | V63: =S63-(T63+U63) -> 0 | W63: =SUMIFS($BN$9:$BN$41,$N$9:$N$41,R63,$C$9:$C$41,"YES")+SUMIFS($BN$9:$BN$41,$N$9:$N$41,R63,$C$9:$C$41,"YES-OOS") -> 0 | X63: =SUMIFS($BO$9:$BO$41,$N$9:$N$41,R63,$C$9:$C$41,"YES")+SUMIFS($BO$9:$BO$41,$N$9:$N$41,R63,$C$9:$C$41,"YES-OOS") -> 0 | Y63: =SUMIFS($BP$9:$BP$41,$N$9:$N$41,R63,$C$9:$C$41,"YES")+SUMIFS($BP$9:$BP$41,$N$9:$N$41,R63,$C$9:$C$41,"YES-OOS") -> 0 | Z63: =SUM(W63:Y63) -> 0 | AQ63: =Z63-T63 -> 0
R64: 2 | S64: =SUMIF($N$9:$N$41,R64,$AE$9:$AE$41) -> 0 | T64: =SUMIFS($BQ$9:$BQ$41,$N$9:$N$41,R64,$C$9:$C$41,"YES")+SUMIFS($BQ$9:$BQ$41,$N$9:$N$41,R64,$C$9:$C$41,"YES-OOS") -> 0 | U64: =SUMIFS($BQ$9:$BQ$41,$N$9:$N$41,R64,$C$9:$C$41,"PENDING") -> 0 | V64: =S64-(T64+U64) -> 0 | W64: =SUMIFS($BN$9:$BN$41,$N$9:$N$41,R64,$C$9:$C$41,"YES")+SUMIFS($BN$9:$BN$41,$N$9:$N$41,R64,$C$9:$C$41,"YES-OOS") -> 0 | X64: =SUMIFS($BO$9:$BO$41,$N$9:$N$41,R64,$C$9:$C$41,"YES")+SUMIFS($BO$9:$BO$41,$N$9:$N$41,R64,$C$9:$C$41,"YES-OOS") -> 0 | Y64: =SUMIFS($BP$9:$BP$41,$N$9:$N$41,R64,$C$9:$C$41,"YES")+SUMIFS($BP$9:$BP$41,$N$9:$N$41,R64,$C$9:$C$41,"YES-OOS") -> 0 | Z64: =SUM(W64:Y64) -> 0 | AQ64: =Z64-T64 -> 0
R65: 3 | S65: =SUMIF($N$9:$N$41,R65,$AE$9:$AE$41) -> 0 | T65: =SUMIFS($BQ$9:$BQ$41,$N$9:$N$41,R65,$C$9:$C$41,"YES")+SUMIFS($BQ$9:$BQ$41,$N$9:$N$41,R65,$C$9:$C$41,"YES-OOS") -> 0 | U65: =SUMIFS($BQ$9:$BQ$41,$N$9:$N$41,R65,$C$9:$C$41,"PENDING") -> 0 | V65: =S65-(T65+U65) -> 0 | W65: =SUMIFS($BN$9:$BN$41,$N$9:$N$41,R65,$C$9:$C$41,"YES")+SUMIFS($BN$9:$BN$41,$N$9:$N$41,R65,$C$9:$C$41,"YES-OOS") -> 0 | X65: =SUMIFS($BO$9:$BO$41,$N$9:$N$41,R65,$C$9:$C$41,"YES")+SUMIFS($BO$9:$BO$41,$N$9:$N$41,R65,$C$9:$C$41,"YES-OOS") -> 0 | Y65: =SUMIFS($BP$9:$BP$41,$N$9:$N$41,R65,$C$9:$C$41,"YES")+SUMIFS($BP$9:$BP$41,$N$9:$N$41,R65,$C$9:$C$41,"YES-OOS") -> 0 | Z65: =SUM(W65:Y65) -> 0 | AQ65: =Z65-T65 -> 0
...

Sheet Talent & Extras
B1: Production Tax Incentives Talent & Extras
AA3: 1st Shoot Day | AB3: 44597
B4: Project Title: | C4: =#REF! -> #REF! | AA4: Last Shoot Day | AB4: 44600
B5: Shoot Date: | C5: =#REF! -> #REF! | G5: DELETE SAMPLE DATA FOR ACTUAL PROJECTS | AA5: Covid End Date | AB5: 44896
B6: Work State: | C6: =#REF! -> #REF! | AR6: Don't edit this part; with formulas | BG6: (Handling Fees & W/C)
V7: INVOICE/ PROOF OF PAYMENT | Z7: RESIDENCY | BG7: Ineligible
B8: ITEM # | C8: Qualify? | D8: Included on PTIP Report? | E8: Amount Included on PTIP Report | F8: Work State | G8: Talent Name | H8: Title | I8: No. of Work Days | J8: Work Dates | K8: Invoice # | L8: Invoice Date | M8: Wages $ | N8: Misc Pymt/ Agent Fee | O8: ER Payroll Tax | P8: Worker's Comp | Q8: Handling | R8: SAG (P&H) $ | S8: Signatory Fee | T8: Total | U8: PTIP_Check | V8: Received_Invoice | W8: Pymt Method | X8: Payment Entity | Y8: Type | Z8: Document Type | AA8: Issue Date | AB8: Expiration Date | AC8: Home Address | AD8: City | AE8: State | AF8: Zip | AG8: NO-IL Residency Status | AH8: W-9 | AK8: Notes: | AL8: Job No. | AM8: Client Billing No. | AN8: Commercial Id | AO8: Commercial Title | AP8: CPA Tab | AR8: Talent Name | AS8: Title | AT8: Home Address | AU8: City | AV8: Zip | AW8: No. of Work Days | AX8: GROSS | AY8: PAYROLL TAXES | AZ8: BENEFITS (P, H & W) | BA8: CPA TOTAL | BC8: Invoice # | BD8: Work Dates
AX9: =M9+N9 -> 0 | AY9: =O9 -> 0 | AZ9: =R9 -> 0 | BA9: =SUM(AX9:AZ9) -> 0 | BG9: =T9-BA9 -> 0 | BH9: =BG9-Q9-P9 -> 0
B10: 1 | M10: 0 | N10: 0 | O10: 0 | P10: 0 | Q10: 0 | R10: 0 | S10: 0 | T10: =SUM(M10:S10) -> 0 | U10: =E10-T10 -> 0 | AR10: =G10 -> 0 | AS10: =H10 -> 0 | AT10: =I10 -> 0 | AU10: =AD10 -> 0 | AV10: =AF10 -> 0 | AW10: =I10 -> 0 | AX10: =M10+N10 -> 0 | AY10: =O10 -> 0 | AZ10: =R10 -> 0 | BA10: =SUM(AX10:AZ10) -> 0 | BC10: =K10 -> 0 | BD10: =J10 -> 0 | BE10: =BA10-T10+Q10+P10 -> 0 | BG10: =T10-BA10 -> 0 | BH10: =BG10-Q10-P10 -> 0
B11: 2 | M11: 0 | N11: 0 | O11: 0 | P11: 0 | Q11: 0 | R11: 0 | S11: 0 | T11: =SUM(M11:S11) -> 0 | U11: =E11-T11 -> 0 | AR11: =G11 -> 0 | AS11: =H11 -> 0 | AT11: =I11 -> 0 | AU11: =AD11 -> 0 | AV11: =AF11 -> 0 | AW11: =I11 -> 0 | AX11: =M11+N11 -> 0 | AY11: =O11 -> 0 | AZ11: =R11 -> 0 | BA11: =SUM(AX11:AZ11) -> 0 | BC11: =K11 -> 0 | BD11: =J11 -> 0 | BE11: =BA11-T11+Q11+P11 -> 0 | BG11: =T11-BA11 -> 0 | BH11: =BG11-Q11-P11 -> 0
B12: 3 | M12: 0 | N12: 0 | O12: 0 | P12: 0 | Q12: 0 | R12: 0 | S12: 0 | T12: =SUM(M12:S12) -> 0 | U12: =E12-T12 -> 0 | AR12: =G12 -> 0 | AS12: =H12 -> 0 | AT12: =I12 -> 0 | AU12: =AD12 -> 0 | AV12: =AF12 -> 0 | AW12: =I12 -> 0 | AX12: =M12+N12 -> 0 | AY12: =O12 -> 0 | AZ12: =R12 -> 0 | BA12: =SUM(AX12:AZ12) -> 0 | BC12: =K12 -> 0 | BD12: =J12 -> 0 | BE12: =BA12-T12+Q12+P12 -> 0 | BG12: =T12-BA12 -> 0 | BH12: =BG12-Q12-P12 -> 0
B13: 4 | M13: 0 | N13: 0 | O13: 0 | P13: 0 | Q13: 0 | R13: 0 | S13: 0 | T13: =SUM(M13:S13) -> 0 | U13: =E13-T13 -> 0 | AR13: =G13 -> 0 | AS13: =H13 -> 0 | AT13: =I13 -> 0 | AU13: =AD13 -> 0 | AV13: =AF13 -> 0 | AW13: =I13 -> 0 | AX13: =M13+N13 -> 0 | AY13: =O13 -> 0 | AZ13: =R13 -> 0 | BA13: =SUM(AX13:AZ13) -> 0 | BC13: =K13 -> 0 | BD13: =J13 -> 0 | BE13: =BA13-T13+Q13+P13 -> 0 | BG13: =T13-BA13 -> 0 | BH13: =BG13-Q13-P13 -> 0
B14: 5 | M14: 0 | N14: 0 | O14: 0 | P14: 0 | Q14: 0 | R14: 0 | S14: 0 | T14: =SUM(M14:S14) -> 0 | U14: =E14-T14 -> 0 | AR14: =G14 -> 0 | AS14: =H14 -> 0 | AT14: =I14 -> 0 | AU14: =AD14 -> 0 | AV14: =AF14 -> 0 | AW14: =I14 -> 0 | AX14: =M14+N14 -> 0 | AY14: =O14 -> 0 | AZ14: =R14 -> 0 | BA14: =SUM(AX14:AZ14) -> 0 | BC14: =K14 -> 0 | BD14: =J14 -> 0 | BE14: =BA14-T14+Q14+P14 -> 0 | BG14: =T14-BA14 -> 0 | BH14: =BG14-Q14-P14 -> 0
B15: 6 | M15: 0 | N15: 0 | O15: 0 | P15: 0 | Q15: 0 | R15: 0 | S15: 0 | T15: =SUM(M15:S15) -> 0 | U15: =E15-T15 -> 0 | AR15: =G15 -> 0 | AS15: =H15 -> 0 | AT15: =I15 -> 0 | AU15: =AD15 -> 0 | AV15: =AF15 -> 0 | AW15: =I15 -> 0 | AX15: =M15+N15 -> 0 | AY15: =O15 -> 0 | AZ15: =R15 -> 0 | BA15: =SUM(AX15:AZ15) -> 0 | BC15: =K15 -> 0 | BD15: =J15 -> 0 | BE15: =BA15-T15+Q15+P15 -> 0 | BG15: =T15-BA15 -> 0 | BH15: =BG15-Q15-P15 -> 0
B16: 7 | M16: 0 | N16: 0 | O16: 0 | P16: 0 | Q16: 0 | R16: 0 | S16: 0 | T16: =SUM(M16:S16) -> 0 | U16: =E16-T16 -> 0 | AR16: =G16 -> 0 | AS16: =H16 -> 0 | AT16: =I16 -> 0 | AU16: =AD16 -> 0 | AV16: =AF16 -> 0 | AW16: =I16 -> 0 | AX16: =M16+N16 -> 0 | AY16: =O16 -> 0 | AZ16: =R16 -> 0 | BA16: =SUM(AX16:AZ16) -> 0 | BC16: =K16 -> 0 | BD16: =J16 -> 0 | BE16: =BA16-T16+Q16+P16 -> 0 | BG16: =T16-BA16 -> 0 | BH16: =BG16-Q16-P16 -> 0
B17: 8 | M17: 0 | N17: 0 | O17: 0 | P17: 0 | Q17: 0 | R17: 0 | S17: 0 | T17: =SUM(M17:S17) -> 0 | U17: =E17-T17 -> 0 | AR17: =G17 -> 0 | AS17: =H17 -> 0 | AT17: =I17 -> 0 | AU17: =AD17 -> 0 | AV17: =AF17 -> 0 | AW17: =I17 -> 0 | AX17: =M17+N17 -> 0 | AY17: =O17 -> 0 | AZ17: =R17 -> 0 | BA17: =SUM(AX17:AZ17) -> 0 | BC17: =K17 -> 0 | BD17: =J17 -> 0 | BE17: =BA17-T17+Q17+P17 -> 0 | BG17: =T17-BA17 -> 0 | BH17: =BG17-Q17-P17 -> 0
B18: 9 | M18: 0 | N18: 0 | O18: 0 | P18: 0 | Q18: 0 | R18: 0 | S18: 0 | T18: =SUM(M18:S18) -> 0 | U18: =E18-T18 -> 0 | AR18: =G18 -> 0 | AS18: =H18 -> 0 | AT18: =I18 -> 0 | AU18: =AD18 -> 0 | AV18: =AF18 -> 0 | AW18: =I18 -> 0 | AX18: =M18+N18 -> 0 | AY18: =O18 -> 0 | AZ18: =R18 -> 0 | BA18: =SUM(AX18:AZ18) -> 0 | BC18: =K18 -> 0 | BD18: =J18 -> 0 | BE18: =BA18-T18+Q18+P18 -> 0 | BG18: =T18-BA18 -> 0 | BH18: =BG18-Q18-P18 -> 0
B19: 10 | M19: 0 | N19: 0 | O19: 0 | P19: 0 | Q19: 0 | R19: 0 | S19: 0 | T19: =SUM(M19:S19) -> 0 | U19: =E19-T19 -> 0 | AR19: =G19 -> 0 | AS19: =H19 -> 0 | AT19: =I19 -> 0 | AU19: =AD19 -> 0 | AV19: =AF19 -> 0 | AW19: =I19 -> 0 | AX19: =M19+N19 -> 0 | AY19: =O19 -> 0 | AZ19: =R19 -> 0 | BA19: =SUM(AX19:AZ19) -> 0 | BC19: =K19 -> 0 | BD19: =J19 -> 0 | BE19: =BA19-T19+Q19+P19 -> 0 | BG19: =T19-BA19 -> 0 | BH19: =BG19-Q19-P19 -> 0
B20: 11 | M20: 0 | N20: 0 | O20: 0 | P20: 0 | Q20: 0 | R20: 0 | S20: 0 | T20: =SUM(M20:S20) -> 0 | U20: =E20-T20 -> 0 | AR20: =G20 -> 0 | AS20: =H20 -> 0 | AT20: =I20 -> 0 | AU20: =AD20 -> 0 | AV20: =AF20 -> 0 | AW20: =I20 -> 0 | AX20: =M20+N20 -> 0 | AY20: =O20 -> 0 | AZ20: =R20 -> 0 | BA20: =SUM(AX20:AZ20) -> 0 | BC20: =K20 -> 0 | BD20: =J20 -> 0 | BE20: =BA20-T20+Q20+P20 -> 0 | BG20: =T20-BA20 -> 0 | BH20: =BG20-Q20-P20 -> 0
