Workbook
Name OLE_LINK1: #REF!

Sheet Overview
A1: TPC
A2: Commercial Project Summary
B4: Project Description | F4: State: | G4: TX
B5: Project Title:
B7: Award Date
B8: Pre Pro Date
B9: Shoot Date | C9: 46068 | G9: Estimated Production Budget
B10: Production Wrap Date | H10: In-State: | I10: Out of State | J10: Total
B11: Post Production Date | J11: 0 | K11: Estimated Total
J12: 0 | K12: Prodco direct costs
B13: Client: | G13: Total: | H13: =SUM(H11:H12) -> 0 | I13: =SUM(I11:I12) -> 0
B14: Client Brand:
B15: Product: | G15: Submitted: | J15: Qualified | M15: DNQ
B16: Agency: | D16: OOS Agency | G16: Production | H16: ='AP (POs + Reimbursement)'!F92 -> 0 | J16: Production | K16: ='AP (POs + Reimbursement)'!H101 -> 0 | M16: =K16-H16 -> 0
B17: Production Company: | D17: OOS ProdCo | G17: Prod. Crew Reimb. | H17: =#REF!+#REF! -> #REF! | J17: Prod. Crew Reimb. | K17: =#REF!+#REF! -> #REF! | M17: =K17-H17 -> #REF!
B18: Crew Payroll Company: | G18: Petty Cash | H18: ='Petty Cash'!G111 -> 0 | J18: Petty Cash | K18: ='Petty Cash'!I120 -> 0 | M18: =K18-H18 -> 0
B19: Celebrity Payroll Company: | G19: Crew Payroll (3rd Party) | H19: ='Crew Payroll'!AA58 -> 0 | J19: Crew Payroll (3rd Party) | K19: ='Crew Payroll'!AA67 -> 0 | M19: =K19-H19 -> 0
B20: Talent Payroll Company: | G20: Crew Payroll (Independent Contractors) | H20: ='Crew - Indepen. Contractors'!I54 -> 0 | J20: Crew Payroll (Independent Contractors) | K20: ='Crew - Indepen. Contractors'!I52 -> 0 | M20: =K20-H20 -> 0
B21: Production Insurance: | G21: Talent Payroll | H21: ='Talent Payroll'!U43 -> 0 | J21: Talent Payroll | K21: ='Talent Payroll'!S52 -> 0 | M21: =K21-H21 -> 0
B22: Other Payor 2: | G22: Agency | H22: ='Agency Vendor Exps'!H33 -> 0 | J22: Agency | K22: ='Agency Vendor Exps'!H42 -> 0 | M22: =K22-H22 -> 0
B23: Other Payor 3: | G23: Other | H23: 0 | J23: Other | K23: =H23 -> 0 | M23: =K23-H23 -> 0
B25: Celebrity Name(s): | G25: Total Submitted costs: | H25: =SUM(H16:H24) -> #REF! | J25: Total Submitted costs: | K25: =SUM(K16:K24) -> #REF! | M25: =SUM(M16:M24) -> #REF!
B27: Job Description: | J27: Submitted Payroll Expenditures: | K27: =K19+K20+K21 -> 0
B28: Agency Job Name: | J28: Submitted AP Expenditures: | K28: =#REF!+#REF!+K22 -> #REF!
B29: Agency Job Number: | J29: Submitted PC/CC Expenditures: | K29: =K18+#REF!+#REF! -> #REF!
J30: Total Submitted Expenditures: | K30: =SUM(K27:K29) -> #REF!
C31: AICP Bid
C32: AICP Bid TX Only | K32: Actuals | M32: Maximum Allowed
C33: Award Letter | I33: Qualifying Spending: | K33: =K30 -> #REF! | M33: 229533.33
C34: Grant Agreement | I34: Anticipated Grant Pct: | K34: 0.05 | M34: 0.075
C35: Call Sheet | I35: Estimated Grant Amount: | K35: =K33*K34 -> #REF! | M35: =M33*M34 -> 17215
C36: Production Contract
J37: Amount Issued | M37: Per Michelle Habecker on X/XX/21
C38: Application
C39: Agency Estimate
C40: Pre-Production Book
B41: Spots:
C43: UPLIFTS FOR THIS JOB
C44: Rural Area (2.5% | E44: FALSE
C45: Post Production (1%) | E45: FALSE
...

Sheet Checklist
A3: W-9 for All Vendors
A4: Since ineligible amounts were removed, should we modify the receipt?
A5: CPA Audit | B5: No
A6: Loan-out Registration | B6: No
A7: Income tax withholding | B7: Not required for both individual and loan-out
A9: Have we gotten DTRs from All Crew Listed on the Callsheet? | B9: FALSE
A10: Have we gotten DTRs from All Crew Listed on the Payroll Report? | B10: FALSE
A11: Have we gotten DTRs from All Crew Listed on the Invoices? | B11: FALSE
A12: Have we gotten DTRs from All Talent Listed on the Callsheet? | B12: FALSE
A13: Have we gotten DTRs from All Talent Listed on the Payroll Report? | B13: FALSE
A14: Are all DTRs verified by the production Company? | B14: FALSE
A15: Have Driver's licences been put into the Database? | B15: FALSE

Sheet Locations
C2: PRODUCTION LOCATIONS
L3: Any County EXCEPT the following will qualify for Rural Uplift:
A4: Shoot Day | B4: Location Name | C4: Street Number | D4: Street Name | E4: City | F4: State | G4: Zip Code | H4: Production Date/Range | I4: Notes (Basecamp, Non-TX) | J4: TX County | L4: Harris
L5: Dallas
L6: Tarrant
L7: Bexar
L8: Travis
L9: Collin
L10: Denton
L11: Fort Bend
L12: Hidalgo
L13: El Paso
L14: Montgomery
L15: Williamson
L16: Cameron
... L21: Lubbock

Sheet Cast & Crew List
C2: CAST & CREW LIST
D3: Alphabetized by Last Name
C4: Crew Or Talent | D4: Name (Last, First) | E4: Crew Position / Role | F4: DTR Form (Y/N) | G4: Parent Name (for Minors) | H4: Notes | I4: From Documents | K4: 1st Shoot date | L4: =Overview!C9 -> 46068
B5: 1 | K5: 120 Days Prior to Shoot date | L5: =L4-120 -> 45948
B6: 2
B7: 3 | K7: TOTAL TX ONLY - CREW & CAST | L7: =COUNTIF(F5:F89,"Y") -> 0
B8: 4 | K8: TOTAL ALL CREW & CAST | L8: =COUNTA(C5:C90) -> 0
B9: 5 | K9: TX ONLY % | L9: =L7/L8 -> #DIV/0!
B10: 6
B11: 7
B12: 8
B13: 9
B14: 10
B15: 11
B16: 12
B17: 13
B18: 14
B19: 15
B20: 16
B21: 17
... B89: 85

Sheet Crew Payroll
I3: 35% of paid crew must be Texas Residents
T4: W/C & Handling Fees DNQ unless a local vendor was used
T5: ***typically payroll companies are self-insured - as such DNQ | AB5: If applicable
H7: Check# to Reference# | AT7: CPA | AY7: Ineligible
B8: ITEM # | C8: Production Report | D8: Invoice PDF | E8: Inv # | F8: Invoice Date | G8: Pay Period (WE) | H8: Ref Number | I8: Crew Name (Last, First) | J8: Crew Position | K8: Valid DTR Form | L8: Work State | M8: Resident State | N8: Taxable Wages $ | O8: Corporate $ | P8: FICA | Q8: Medi | R8: FUI | S8: SUI | T8: W/C | U8: PH&W | V8: Vac/Hol | W8: Hand | X8: Non Taxable - Mileage | Y8: Non Taxable - Kit Rental | Z8: Non Taxable - Other Rental | AA8: Total | AB8: Ineligible $ | AC8: Submitted Amount | AD8: Automation Total | AE8: Automation Check | AF8: Time Allocated | AG8: Proof of Payment | AH8: Payment Entity | AI8: Loan Out | AJ8: Qualify? | AK8: Home address | AL8: City | AM8: State | AN8: Zip | AO8: Notes: | AQ8: On Call Sheet | AR8: Name on Call sheet | AT8: GROSS | AU8: BENEFITS (P, H & W) | AV8: TOTAL
B9: 1 | AA9: =SUM(N9:Z9) -> 0 | AB9: =T9+W9 -> 0 | AC9: =AA9-AB9 -> 0 | AE9: =AA9-AD9 -> 0 | AT9: =N9+O9+P9+Q9+R9 -> 0 | AU9: =S9+T9+U9+V9+X9+Y9 -> 0 | AV9: =SUM(AT9:AU9) -> 0 | AW9: =AV9-AA9+W9+Z9 -> 0 | AY9: =AA9-AV9 -> 0 | AZ9: =AY9-AB9 -> 0
B10: 2 | AA10: =SUM(N10:Z10) -> 0 | AB10: =T10+W10 -> 0 | AC10: =AA10-AB10 -> 0 | AE10: =AA10-AD10 -> 0 | AT10: =N10+O10+P10+Q10+R10 -> 0 | AU10: =S10+T10+U10+V10+X10+Y10 -> 0 | AV10: =SUM(AT10:AU10) -> 0 | AW10: =AV10-AA10+W10+Z10 -> 0 | AY10: =AA10-AV10 -> 0 | AZ10: =AY10-AB10 -> 0
B11: 3 | AA11: =SUM(N11:Z11) -> 0 | AB11: =T11+W11 -> 0 | AC11: =AA11-AB11 -> 0 | AE11: =AA11-AD11 -> 0 | AT11: =N11+O11+P11+Q11+R11 -> 0 | AU11: =S11+T11+U11+V11+X11+Y11 -> 0 | AV11: =SUM(AT11:AU11) -> 0 | AW11: =AV11-AA11+W11+Z11 -> 0 | AY11: =AA11-AV11 -> 0 | AZ11: =AY11-AB11 -> 0
B12: 4 | AA12: =SUM(N12:Z12) -> 0 | AB12: =T12+W12 -> 0 | AC12: =AA12-AB12 -> 0 | AE12: =AA12-AD12 -> 0 | AT12: =N12+O12+P12+Q12+R12 -> 0 | AU12: =S12+T12+U12+V12+X12+Y12 -> 0 | AV12: =SUM(AT12:AU12) -> 0 | AW12: =AV12-AA12+W12+Z12 -> 0 | AY12: =AA12-AV12 -> 0 | AZ12: =AY12-AB12 -> 0
B13: 5 | AA13: =SUM(N13:Z13) -> 0 | AB13: =T13+W13 -> 0 | AC13: =AA13-AB13 -> 0 | AE13: =AA13-AD13 -> 0 | AT13: =N13+O13+P13+Q13+R13 -> 0 | AU13: =S13+T13+U13+V13+X13+Y13 -> 0 | AV13: =SUM(AT13:AU13) -> 0 | AW13: =AV13-AA13+W13+Z13 -> 0 | AY13: =AA13-AV13 -> 0 | AZ13: =AY13-AB13 -> 0
B14: 6 | AA14: =SUM(N14:Z14) -> 0 | AB14: =T14+W14 -> 0 | AC14: =AA14-AB14 -> 0 | AE14: =AA14-AD14 -> 0 | AT14: =N14+O14+P14+Q14+R14 -> 0 | AU14: =S14+T14+U14+V14+X14+Y14 -> 0 | AV14: =SUM(AT14:AU14) -> 0 | AW14: =AV14-AA14+W14+Z14 -> 0 | AY14: =AA14-AV14 -> 0 | AZ14: =AY14-AB14 -> 0
B15: 7 | AA15: =SUM(N15:Z15) -> 0 | AB15: =T15+W15 -> 0 | AC15: =AA15-AB15 -> 0 | AE15: =AA15-AD15 -> 0 | AT15: =N15+O15+P15+Q15+R15 -> 0 | AU15: =S15+T15+U15+V15+X15+Y15 -> 0 | AV15: =SUM(AT15:AU15) -> 0 | AW15: =AV15-AA15+W15+Z15 -> 0 | AY15: =AA15-AV15 -> 0 | AZ15: =AY15-AB15 -> 0
B16: 8 | AA16: =SUM(N16:Z16) -> 0 | AB16: =T16+W16 -> 0 | AC16: =AA16-AB16 -> 0 | AE16: =AA16-AD16 -> 0 | AT16: =N16+O16+P16+Q16+R16 -> 0 | AU16: =S16+T16+U16+V16+X16+Y16 -> 0 | AV16: =SUM(AT16:AU16) -> 0 | AW16: =AV16-AA16+W16+Z16 -> 0 | AY16: =AA16-AV16 -> 0 | AZ16: =AY16-AB16 -> 0
B17: 9 | AA17: =SUM(N17:Z17) -> 0 | AB17: =T17+W17 -> 0 | AC17: =AA17-AB17 -> 0 | AE17: =AA17-AD17 -> 0 | AT17: =N17+O17+P17+Q17+R17 -> 0 | AU17: =S17+T17+U17+V17+X17+Y17 -> 0 | AV17: =SUM(AT17:AU17) -> 0 | AW17: =AV17-AA17+W17+Z17 -> 0 | AY17: =AA17-AV17 -> 0 | AZ17: =AY17-AB17 -> 0
B18: 10 | AA18: =SUM(N18:Z18) -> 0 | AB18: =T18+W18 -> 0 | AC18: =AA18-AB18 -> 0 | AE18: =AA18-AD18 -> 0 | AT18: =N18+O18+P18+Q18+R18 -> 0 | AU18: =S18+T18+U18+V18+X18+Y18 -> 0 | AV18: =SUM(AT18:AU18) -> 0 | AW18: =AV18-AA18+W18+Z18 -> 0 | AY18: =AA18-AV18 -> 0 | AZ18: =AY18-AB18 -> 0
B19: 11 | AA19: =SUM(N19:Z19) -> 0 | AB19: =T19+W19 -> 0 | AC19: =AA19-AB19 -> 0 | AE19: =AA19-AD19 -> 0 | AT19: =N19+O19+P19+Q19+R19 -> 0 | AU19: =S19+T19+U19+V19+X19+Y19 -> 0 | AV19: =SUM(AT19:AU19) -> 0 | AW19: =AV19-AA19+W19+Z19 -> 0 | AY19: =AA19-AV19 -> 0 | AZ19: =AY19-AB19 -> 0
B20: 12 | AA20: =SUM(N20:Z20) -> 0 | AB20: =T20+W20 -> 0 | AC20: =AA20-AB20 -> 0 | AE20: =AA20-AD20 -> 0 | AT20: =N20+O20+P20+Q20+R20 -> 0 | AU20: =S20+T20+U20+V20+X20+Y20 -> 0 | AV20: =SUM(AT20:AU20) -> 0 | AW20: =AV20-AA20+W20+Z20 -> 0 | AY20: =AA20-AV20 -> 0 | AZ20: =AY20-AB20 -> 0
... B54: 46 | AA54: =SUM(N54:Z54) -> 0 | AB54: =T54+W54 -> 0 | AC54: =AA54-AB54 -> 0 | AE54: =AA54-AD54 -> 0 | AT54: =N54+O54+P54+Q54+R54 -> 0 | AU54: =S54+T54+U54+V54+X54+Y54 -> 0 | AV54: =SUM(AT54:AU54) -> 0 | AW54: =AV54-AA54+W54+Z54 -> 0 | AY54: =AA54-AV54 -> 0 | AZ54: =AY54-AB54 -> 0
N55: =SUBTOTAL(9,N9:N54) -> 0 | O55: =SUBTOTAL(9,O9:O54) -> 0 | P55: =SUBTOTAL(9,P9:P54) -> 0 | Q55: =SUBTOTAL(9,Q9:Q54) -> 0 | R55: =SUBTOTAL(9,R9:R54) -> 0 | S55: =SUBTOTAL(9,S9:S54) -> 0 | T55: =SUBTOTAL(9,T9:T54) -> 0 | U55: =SUBTOTAL(9,U9:U54) -> 0 | ... AC55: =SUBTOTAL(9,AC9:AC54) -> 0 | AT55: =SUBTOTAL(9,AT9:AT54) -> 0 | AU55: =SUBTOTAL(9,AU9:AU54) -> 0 | AV55: =SUBTOTAL(9,AV9:AV54) -> 0 | AW55: =AV55-AA55+W55+Z55 -> 0 | AY55: =SUM(AY9:AY54) -> 0
AT57: =SUM(AT9:AT54) -> 0 | AU57: =SUM(AU9:AU54) -> 0 | AV57: =SUM(AV9:AV54) -> 0 | AY57: =SUM(AY9:AY54) -> 0
N58: =SUM(N9:N54) -> 0 | O58: =SUM(O9:O54) -> 0 | P58: =SUM(P9:P54) -> 0 | Q58: =SUM(Q9:Q54) -> 0 | R58: =SUM(R9:R54) -> 0 | S58: =SUM(S9:S54) -> 0 | T58: =SUM(T9:T54) -> 0 | U58: =SUM(U9:U54) -> 0 | ... AC58: =SUM(AC9:AC54) -> 0
F59: Invoice # | G59: Total | H59: Qualified Amount | I59: Unqualified Amount
G60: =SUMIF($E$9:$E$54,$F60,$AA$9:$AA$54) -> 0 | H60: =SUMIFS($AC$9:$AC$54,$AJ$9:$AJ$54,"YES",$E$9:$E$54,$F60) -> 0 | I60: =G60-H60 -> 0
G61: =SUMIF($E$9:$E$54,$F61,$AA$9:$AA$54) -> 0 | H61: =SUMIFS($AC$9:$AC$54,$AJ$9:$AJ$54,"YES",$E$9:$E$54,$F61) -> 0 | I61: =G61-H61 -> 0
G62: =SUMIF($E$9:$E$54,$F62,$AA$9:$AA$54) -> 0 | H62: =SUMIFS($AC$9:$AC$54,$AJ$9:$AJ$54,"YES",$E$9:$E$54,$F62) -> 0 | I62: =G62-H62 -> 0 | W62: ELIGIBLE TOTAL | AB62: INELIGIBLE TOTAL
G63: =SUMIF($E$9:$E$54,$F63,$AA$9:$AA$54) -> 0 | H63: =SUMIFS($AC$9:$AC$54,$AJ$9:$AJ$54,"YES",$E$9:$E$54,$F63) -> 0 | I63: =G63-H63 -> 0 | W63: NO-OOS | X63: NO-TX | Y63: YES | AB63: NO-OOS | AC63: NO-TX | AF63: YES
F64: Total | G64: =SUM(G60:G63) -> 0 | H64: =SUM(H60:H63) -> 0 | I64: =SUM(I60:I63) -> 0 | W64: =SUMIF($AJ$9:$AJ$54,W63,$AV$9:$AV$54) -> 0 | X64: =SUMIF($AJ$9:$AJ$54,X63,$AV$9:$AV$54) -> 0 | Y64: =SUMIF($AJ$9:$AJ$54,Y63,$AV$9:$AV$54) -> 0 | Z64: =SUM(W64:Y64) -> 0 | AB64: =SUMIF($AJ$9:$AJ$54,AB63,$AY$9:$AY$54) -> 0 | AC64: =SUMIF($AJ$9:$AJ$54,AC63,$AY$9:$AY$54) -> 0 | AF64: =SUMIF($AJ$9:$AJ$54,AF63,$AY$9:$AY$54) -> 0 | AG64: =SUM(AB64:AF64) -> 0
G65: =G64-AA58 -> 0 | H65: =H64-AA67 -> 0 | I65: =I64-AA68 -> 0 | Z65: =Z64-AV57 -> 0 | AG65: =AG64-AY57 -> 0
Z67: Total Eligible | AA67: =Y64 -> 0
Z68: Total Ineligible | AA68: =W64+X64+AB64+AC64+AF64 -> 0
Z69: Total Expenses | AA69: =SUM(AA67:AA68) -> 0
AA70: =AA69-AA58 -> 0

Sheet Crew - Indepen. Contractors
F7: Pay period to Check Number
A8: - | B8: ITEM # | C8: PO # | D8: Invoice # | E8: Pay Period/Invoice Date | F8: Check Number | G8: Gross Wages | H8: Mileage | I8: Kit Rental | J8: Other | K8: Total Ineligible | L8: Submitted Amount $ | M8: Crew Name (Last, First) | N8: Crew Position | O8: Valid DTR Form | P8: Pymt Method | Q8: Pymt # | R8: Proof of Payment? | S8: Payment Entity | T8: Type | U8: Description | V8: Address | W8: City | X8: State | Y8: Zip | Z8: Contact # | AA8: Qualify? | AB8: Notes: | AD8: On Call Sheet | AE8: Name on Call sheet
B9: 1 | G9: 0 | H9: 0 | I9: 0 | J9: 0 | K9: 0 | L9: =SUM(G9:J9)-K9 -> 0
B10: 2 | G10: 0 | H10: 0 | I10: 0 | J10: 0 | K10: 0 | L10: =SUM(G10:J10)-K10 -> 0
B11: 3 | G11: 0 | H11: 0 | I11: 0 | J11: 0 | K11: 0 | L11: =SUM(G11:J11)-K11 -> 0
B12: 4 | G12: 0 | H12: 0 | I12: 0 | J12: 0 | K12: 0 | L12: =SUM(G12:J12)-K12 -> 0
B13: 5 | G13: 0 | H13: 0 | I13: 0 | J13: 0 | K13: 0 | L13: =SUM(G13:J13)-K13 -> 0
B14: 6 | G14: 0 | H14: 0 | I14: 0 | J14: 0 | K14: 0 | L14: =SUM(G14:J14)-K14 -> 0
B15: 7 | G15: 0 | H15: 0 | I15: 0 | J15: 0 | K15: 0 | L15: =SUM(G15:J15)-K15 -> 0
B16: 8 | G16: 0 | H16: 0 | I16: 0 | J16: 0 | K16: 0 | L16: =SUM(G16:J16)-K16 -> 0
B17: 9 | G17: 0 | H17: 0 | I17: 0 | J17: 0 | K17: 0 | L17: =SUM(G17:J17)-K17 -> 0
B18: 10 | G18: 0 | H18: 0 | I18: 0 | J18: 0 | K18: 0 | L18: =SUM(G18:J18)-K18 -> 0
B19: 11 | G19: 0 | H19: 0 | I19: 0 | J19: 0 | K19: 0 | L19: =SUM(G19:J19)-K19 -> 0
B20: 12 | G20: 0 | H20: 0 | I20: 0 | J20: 0 | K20: 0 | L20: =SUM(G20:J20)-K20 -> 0
... B38: 30 | G38: 0 | H38: 0 | I38: 0 | J38: 0 | K38: 0 | L38: =SUM(G38:J38)-K38 -> 0
G39: 0 | H39: 0 | I39: 0 | J39: 0 | K39: 0 | L39: =SUM(G39:J39)-K39 -> 0
G40: =SUBTOTAL(9,G9:G39) -> 0 | H40: =SUBTOTAL(9,H9:H39) -> 0 | I40: =SUBTOTAL(9,I9:I39) -> 0 | J40: =SUBTOTAL(9,J9:J39) -> 0 | K40: =SUBTOTAL(9,K9:K39) -> 0 | L40: =SUBTOTAL(9,L9:L39) -> 0 | Q40: =SUBTOTAL(2,Q9:Q39) -> 0
H43: 'Comm Summary'!A1 | I43: 'Comm Summary'!A1 | J43: 'Comm Summary'!A1 | K43: 'Comm Summary'!A1 | L43: =SUM(L9:L39) -> 0
D47: ELIGIBLE TOTAL | J47: INELIGIBLE TOTAL
D48: NO-OOS | E48: NO-TX | F48: NO-TX | G48: YES | J48: NO-OOS | K48: NO-TX | L48: YES
D49: =SUMIF($AA$9:$AA$38,D48,$L$9:$L$39) -> 0 | E49: =SUMIF($AA$9:$AA$38,E48,$L$9:$L$39) -> 0 | F49: =SUMIF($AA$9:$AA$38,F48,$L$9:$L$39) -> 0 | G49: =SUMIF($AA$9:$AA$38,G48,$L$10:$L$40) -> 0 | H49: =SUM(D49:G49) -> 0 | J49: =SUMIF($AA$9:$AA$38,J48,$K$9:$K$38) -> 0 | K49: =SUMIF($AA$9:$AA$38,K48,$K$9:$K$38) -> 0 | L49: =SUMIF($AA$9:$AA$38,L48,$K$9:$K$38) -> 0 | M49: =SUM(J49:L49) -> 0
H50: =L43-H49 -> 0 | M50: =K43-M49 -> #VALUE!
H52: Total Eligible | I52: =G49 -> 0
H53: Total Ineligible | I53: =D49+E49+J49+K49+L49 -> 0
H54: Total Expenses | I54: =SUM(I52:I53) -> 0
I55: =G43-I54 -> 0

Sheet Talent Payroll
V3: 35% of paid cast & crew, including extras, must be Texas Residents
V4: Add a column for who paid the talent (Prodco vs Agency) if needed
Q5: Taxes need to be broken Down: FICA, FUTA MEDI, SUTA
M7: Include | O7: Include | Q7: Include | S7: Include | T7: Include | W7: Include | AB7: Include | AI7: Include | AK7: CPA | AP7: Ineligible
B8: ITEM # | C8: On PTIP | D8: On PDF | E8: Invoice # | F8: Invoice Date | G8: Ref Number (Check #) | H8: Talent Name | I8: Title | J8: Valid DTR Form | K8: Location | L8: TX Resident | M8: Gross Wages $ | N8: Misc Payment | O8: Mileage | P8: Kit Rental | Q8: ER Payroll Taxes | R8: Workers Comp | S8: Handling/Vendor Fee | T8: Pension & Health | U8: Total | V8: Ineligible $ | W8: Submitted Amount | X8: Pymt Method | Y8: Pymt # | Z8: Proof of Payment | AA8: Payment Entity | AB8: Type | AC8: Loan Out | AD8: Qualify? | AE8: Home Address | AF8: City | AG8: State | AH8: Zip | AI8: Notes: | AK8: GROSS | AL8: FRINGES | AM8: TOTAL
B9: 1 | U9: =SUM(M9:T9) -> 0 | V9: =R9 -> 0 | W9: =U9-V9 -> 0 | AK9: =M9+N9+O9 -> 0 | AL9: =Q9+S9+T9 -> 0 | AM9: =SUM(AK9:AL9) -> 0 | AN9: =AM9-W9 -> 0 | AP9: =U9-AM9 -> 0 | AQ9: =AP9-V9 -> 0
B10: 2 | U10: =SUM(M10:T10) -> 0 | V10: =R10 -> 0 | W10: =U10-V10 -> 0 | AK10: =M10+N10+O10 -> 0 | AL10: =Q10+S10+T10 -> 0 | AM10: =SUM(AK10:AL10) -> 0 | AN10: =AM10-W10 -> 0 | AP10: =U10-AM10 -> 0 | AQ10: =AP10-V10 -> 0
B11: 3 | U11: =SUM(M11:T11) -> 0 | V11: =R11 -> 0 | W11: =U11-V11 -> 0 | AK11: =M11+N11+O11 -> 0 | AL11: =Q11+S11+T11 -> 0 | AM11: =SUM(AK11:AL11) -> 0 | AN11: =AM11-W11 -> 0 | AP11: =U11-AM11 -> 0 | AQ11: =AP11-V11 -> 0
B12: 4 | U12: =SUM(M12:T12) -> 0 | V12: =R12 -> 0 | W12: =U12-V12 -> 0 | AK12: =M12+N12+O12 -> 0 | AL12: =Q12+S12+T12 -> 0 | AM12: =SUM(AK12:AL12) -> 0 | AN12: =AM12-W12 -> 0 | AP12: =U12-AM12 -> 0 | AQ12: =AP12-V12 -> 0
B13: 5 | U13: =SUM(M13:T13) -> 0 | V13: =R13 -> 0 | W13: =U13-V13 -> 0 | AK13: =M13+N13+O13 -> 0 | AL13: =Q13+S13+T13 -> 0 | AM13: =SUM(AK13:AL13) -> 0 | AN13: =AM13-W13 -> 0 | AP13: =U13-AM13 -> 0 | AQ13: =AP13-V13 -> 0
B14: 6 | U14: =SUM(M14:T14) -> 0 | V14: =R14 -> 0 | W14: =U14-V14 -> 0 | AK14: =M14+N14+O14 -> 0 | AL14: =Q14+S14+T14 -> 0 | AM14: =SUM(AK14:AL14) -> 0 | AN14: =AM14-W14 -> 0 | AP14: =U14-AM14 -> 0 | AQ14: =AP14-V14 -> 0
B15: 7 | U15: =SUM(M15:T15) -> 0 | V15: =R15 -> 0 | W15: =U15-V15 -> 0 | AK15: =M15+N15+O15 -> 0 | AL15: =Q15+S15+T15 -> 0 | AM15: =SUM(AK15:AL15) -> 0 | AN15: =AM15-W15 -> 0 | AP15: =U15-AM15 -> 0 | AQ15: =AP15-V15 -> 0
B16: 8 | U16: =SUM(M16:T16) -> 0 | V16: =R16 -> 0 | W16: =U16-V16 -> 0 | AK16: =M16+N16+O16 -> 0 | AL16: =Q16+S16+T16 -> 0 | AM16: =SUM(AK16:AL16) -> 0 | AN16: =AM16-W16 -> 0 | AP16: =U16-AM16 -> 0 | AQ16: =AP16-V16 -> 0
B17: 9 | U17: =SUM(M17:T17) -> 0 | V17: =R17 -> 0 | W17: =U17-V17 -> 0 | AK17: =M17+N17+O17 -> 0 | AL17: =Q17+S17+T17 -> 0 | AM17: =SUM(AK17:AL17) -> 0 | AN17: =AM17-W17 -> 0 | AP17: =U17-AM17 -> 0 | AQ17: =AP17-V17 -> 0
B18: 10 | U18: =SUM(M18:T18) -> 0 | V18: =R18 -> 0 | W18: =U18-V18 -> 0 | AK18: =M18+N18+O18 -> 0 | AL18: =Q18+S18+T18 -> 0 | AM18: =SUM(AK18:AL18) -> 0 | AN18: =AM18-W18 -> 0 | AP18: =U18-AM18 -> 0 | AQ18: =AP18-V18 -> 0
B19: 11 | U19: =SUM(M19:T19) -> 0 | V19: =R19 -> 0 | W19: =U19-V19 -> 0 | AK19: =M19+N19+O19 -> 0 | AL19: =Q19+S19+T19 -> 0 | AM19: =SUM(AK19:AL19) -> 0 | AN19: =AM19-W19 -> 0 | AP19: =U19-AM19 -> 0 | AQ19: =AP19-V19 -> 0
B20: 12 | U20: =SUM(M20:T20) -> 0 | V20: =R20 -> 0 | W20: =U20-V20 -> 0 | AK20: =M20+N20+O20 -> 0 | AL20: =Q20+S20+T20 -> 0 | AM20: =SUM(AK20:AL20) -> 0 | AN20: =AM20-W20 -> 0 | AP20: =U20-AM20 -> 0 | AQ20: =AP20-V20 -> 0
... B38: 30 | U38: =SUM(M38:T38) -> 0 | V38: =R38 -> 0 | W38: =U38-V38 -> 0 | AK38: =M38+N38+O38 -> 0 | AL38: =Q38+S38+T38 -> 0 | AM38: =SUM(AK38:AL38) -> 0 | AN38: =AM38-W38 -> 0 | AP38: =U38-AM38 -> 0 | AQ38: =AP38-V38 -> 0
U39: =SUM(M39:T39) -> 0 | V39: =R39 -> 0 | W39: =U39-V39 -> 0
M40: =SUBTOTAL(9,M9:M39) -> 0 | O40: =SUBTOTAL(9,O9:O39) -> 0 | Q40: =SUBTOTAL(9,Q9:Q39) -> 0 | R40: =SUBTOTAL(9,R9:R39) -> 0 | S40: =SUBTOTAL(9,S9:S39) -> 0 | T40: =SUBTOTAL(9,T9:T39) -> 0 | U40: =SUBTOTAL(9,U9:U39) -> 0 | V40: =SUBTOTAL(9,V9:V39) -> 0 | W40: =SUBTOTAL(9,W9:W39) -> 0
M43: =SUM(M9:M39) -> 0 | N43: =SUM(N9:N39) -> 0 | O43: =SUM(O9:O39) -> 0 | Q43: =SUM(Q9:Q39) -> 0 | R43: =SUM(R9:R39) -> 0 | S43: =SUM(S9:S39) -> 0 | T43: =SUM(T9:T39) -> 0 | U43: =SUM(U9:U39) -> 0 | V43: =SUM(V9:V39) -> 0 | W43: =SUM(W9:W39) -> 0 | AK43: =SUM(AK9:AK39) -> 0 | AL43: =SUM(AL9:AL39) -> 0 | AM43: =SUM(AM9:AM39) -> 0 | AP43: =SUM(AP9:AP39) -> 0
E45: Invoice # | F45: Wages & Misc Pymts | H45: Payroll Taxes | I45: P&H Contributions | J45: Handling/Vendor Fee | K45: Total
F46: =SUMIF($E$10:$E$39,E46,$M$9:$M$39)+SUMIF($E$10:$E$39,E46,$O$9:$O$39) -> 0 | H46: =SUMIF($E$10:$E$39,E46,$Q$9:$Q$39)+SUMIF($E$10:$E$39,E46,$R$9:$R$39) -> 0 | I46: =SUMIF($E$10:$E$39,E46,$T$9:$T$39) -> 0 | J46: =SUMIF($E$10:$E$39,E46,$S$9:$S$39) -> 0 | K46: =SUM(F46:J46) -> 0
F47: =SUMIF($E$10:$E$39,E47,$M$9:$M$39)+SUMIF($E$10:$E$39,E47,$O$9:$O$39) -> 0 | H47: =SUMIF($E$10:$E$39,E47,$Q$9:$Q$39)+SUMIF($E$10:$E$39,E47,$R$9:$R$39) -> 0 | I47: =SUMIF($E$10:$E$39,E47,$T$9:$T$39) -> 0 | J47: =SUMIF($E$10:$E$39,E47,$S$9:$S$39) -> 0 | K47: =SUM(F47:J47) -> 0 | O47: ELIGIBLE TOTAL | U47: INELIGIBLE TOTAL
F48: =SUMIF($E$10:$E$39,E48,$M$9:$M$39)+SUMIF($E$10:$E$39,E48,$O$9:$O$39) -> 0 | H48: =SUMIF($E$10:$E$39,E48,$Q$9:$Q$39)+SUMIF($E$10:$E$39,E48,$R$9:$R$39) -> 0 | I48: =SUMIF($E$10:$E$39,E48,$T$9:$T$39) -> 0 | J48: =SUMIF($E$10:$E$39,E48,$S$9:$S$39) -> 0 | K48: =SUM(F48:J48) -> 0 | O48: NO-OOS | P48: NO-TX | Q48: YES | R48: YES-HANDLING | U48: NO-OOS | V48: NO-TX | W48: YES
F49: =SUMIF($E$10:$E$39,E49,$M$9:$M$39)+SUMIF($E$10:$E$39,E49,$O$9:$O$39) -> 0 | H49: =SUMIF($E$10:$E$39,E49,$Q$9:$Q$39)+SUMIF($E$10:$E$39,E49,$R$9:$R$39) -> 0 | I49: =SUMIF($E$10:$E$39,E49,$T$9:$T$39) -> 0 | J49: =SUMIF($E$10:$E$39,E49,$S$9:$S$39) -> 0 | K49: =SUM(F49:J49) -> 0 | O49: =SUMIF($AD$9:$AD$38,O48,$AM$9:$AM$38) -> 0 | P49: =SUMIF($AD$9:$AD$38,P48,$AM$9:$AM$38) -> 0 | Q49: =SUMIF($AD$9:$AD$38,Q48,$AM$9:$AM$38) -> 0 | R49: =SUMIF($AD$9:$AD$38,R48,$AM$9:$AM$38) -> 0 | S49: =SUM(O49:R49) -> 0 | U49: =SUMIF($AD$9:$AD$38,U48,$AP$9:$AP$38) -> 0 | V49: =SUMIF($AD$9:$AD$38,V48,$AP$9:$AP$38) -> 0 | W49: =SUMIF($AD$9:$AD$38,W48,$AP$9:$AP$38) -> 0 | X49: =SUM(U49:W49) -> 0
F50: =SUMIF($E$10:$E$39,E50,$M$9:$M$39)+SUMIF($E$10:$E$39,E50,$O$9:$O$39) -> 0 | H50: =SUMIF($E$10:$E$39,E50,$Q$9:$Q$39)+SUMIF($E$10:$E$39,E50,$R$9:$R$39) -> 0 | I50: =SUMIF($E$10:$E$39,E50,$T$9:$T$39) -> 0 | J50: =SUMIF($E$10:$E$39,E50,$S$9:$S$39) -> 0 | K50: =SUM(F50:J50) -> 0 | S50: =S49-AM43 -> 0 | X50: =X49-AP43 -> 0
F51: =SUMIF($E$10:$E$39,E51,$M$9:$M$39)+SUMIF($E$10:$E$39,E51,$O$9:$O$39) -> 0 | H51: =SUMIF($E$10:$E$39,E51,$Q$9:$Q$39)+SUMIF($E$10:$E$39,E51,$R$9:$R$39) -> 0 | I51: =SUMIF($E$10:$E$39,E51,$T$9:$T$39) -> 0 | J51: =SUMIF($E$10:$E$39,E51,$S$9:$S$39) -> 0 | K51: =SUM(F51:J51) -> 0
F52: =SUMIF($E$10:$E$39,E52,$M$9:$M$39)+SUMIF($E$10:$E$39,E52,$O$9:$O$39) -> 0 | H52: =SUMIF($E$10:$E$39,E52,$Q$9:$Q$39)+SUMIF($E$10:$E$39,E52,$R$9:$R$39) -> 0 | I52: =SUMIF($E$10:$E$39,E52,$T$9:$T$39) -> 0 | J52: =SUMIF($E$10:$E$39,E52,$S$9:$S$39) -> 0 | K52: =SUM(F52:J52) -> 0 | R52: Total Eligible | S52: =Q49 -> 0
F53: =SUMIF($E$10:$E$39,E53,$M$9:$M$39)+SUMIF($E$10:$E$39,E53,$O$9:$O$39) -> 0 | H53: =SUMIF($E$10:$E$39,E53,$Q$9:$Q$39)+SUMIF($E$10:$E$39,E53,$R$9:$R$39) -> 0 | I53: =SUMIF($E$10:$E$39,E53,$T$9:$T$39) -> 0 | J53: =SUMIF($E$10:$E$39,E53,$S$9:$S$39) -> 0 | K53: =SUM(F53:J53) -> 0 | R53: Total Ineligible | S53: =O49+P49+U49+V49+W49 -> 0
F54: =SUMIF($E$10:$E$39,E54,$M$9:$M$39)+SUMIF($E$10:$E$39,E54,$O$9:$O$39) -> 0 | H54: =SUMIF($E$10:$E$39,E54,$Q$9:$Q$39)+SUMIF($E$10:$E$39,E54,$R$9:$R$39) -> 0 | I54: =SUMIF($E$10:$E$39,E54,$T$9:$T$39) -> 0 | J54: =SUMIF($E$10:$E$39,E54,$S$9:$S$39) -> 0 | K54: =SUM(F54:J54) -> 0 | R54: Total Expenses | S54: =SUM(S52:S53) -> 0
F55: =SUMIF($E$10:$E$39,E55,$M$9:$M$39)+SUMIF($E$10:$E$39,E55,$O$9:$O$39) -> 0 | H55: =SUMIF($E$10:$E$39,E55,$Q$9:$Q$39)+SUMIF($E$10:$E$39,E55,$R$9:$R$39) -> 0 | I55: =SUMIF($E$10:$E$39,E55,$T$9:$T$39) -> 0 | J55: =SUMIF($E$10:$E$39,E55,$S$9:$S$39) -> 0 | K55: =SUM(F55:J55) -> 0
F56: =SUMIF($E$10:$E$39,E56,$M$9:$M$39)+SUMIF($E$10:$E$39,E56,$O$9:$O$39) -> 0 | H56: =SUMIF($E$10:$E$39,E56,$Q$9:$Q$39)+SUMIF($E$10:$E$39,E56,$R$9:$R$39) -> 0 | I56: =SUMIF($E$10:$E$39,E56,$T$9:$T$39) -> 0 | J56: =SUMIF($E$10:$E$39,E56,$S$9:$S$39) -> 0 | K56: =SUM(F56:J56) -> 0
F57: =SUMIF($E$10:$E$39,E57,$M$9:$M$39)+SUMIF($E$10:$E$39,E57,$O$9:$O$39) -> 0 | H57: =SUMIF($E$10:$E$39,E57,$Q$9:$Q$39)+SUMIF($E$10:$E$39,E57,$R$9:$R$39) -> 0 | I57: =SUMIF($E$10:$E$39,E57,$T$9:$T$39) -> 0 | J57: =SUMIF($E$10:$E$39,E57,$S$9:$S$39) -> 0 | K57: =SUM(F57:J57) -> 0
F58: =SUMIF($E$10:$E$39,E58,$M$9:$M$39)+SUMIF($E$10:$E$39,E58,$O$9:$O$39) -> 0 | H58: =SUMIF($E$10:$E$39,E58,$Q$9:$Q$39)+SUMIF($E$10:$E$39,E58,$R$9:$R$39) -> 0 | I58: =SUMIF($E$10:$E$39,E58,$T$9:$T$39) -> 0 | J58: =SUMIF($E$10:$E$39,E58,$S$9:$S$39) -> 0 | K58: =SUM(F58:J58) -> 0
F59: =SUMIF($E$10:$E$39,E59,$M$9:$M$39)+SUMIF($E$10:$E$39,E59,$O$9:$O$39) -> 0 | H59: =SUMIF($E$10:$E$39,E59,$Q$9:$Q$39)+SUMIF($E$10:$E$39,E59,$R$9:$R$39) -> 0 | I59: =SUMIF($E$10:$E$39,E59,$T$9:$T$39) -> 0 | J59: =SUMIF($E$10:$E$39,E59,$S$9:$S$39) -> 0 | K59: =SUM(F59:J59) -> 0
F60: =SUMIF($E$10:$E$39,E60,$M$9:$M$39)+SUMIF($E$10:$E$39,E60,$O$9:$O$39) -> 0 | H60: =SUMIF($E$10:$E$39,E60,$Q$9:$Q$39)+SUMIF($E$10:$E$39,E60,$R$9:$R$39) -> 0 | I60: =SUMIF($E$10:$E$39,E60,$T$9:$T$39) -> 0 | J60: =SUMIF($E$10:$E$39,E60,$S$9:$S$39) -> 0 | K60: =SUM(F60:J60) -> 0
F61: =SUMIF($E$10:$E$39,E61,$M$9:$M$39)+SUMIF($E$10:$E$39,E61,$O$9:$O$39) -> 0 | H61: =SUMIF($E$10:$E$39,E61,$Q$9:$Q$39)+SUMIF($E$10:$E$39,E61,$R$9:$R$39) -> 0 | I61: =SUMIF($E$10:$E$39,E61,$T$9:$T$39) -> 0 | J61: =SUMIF($E$10:$E$39,E61,$S$9:$S$39) -> 0 | K61: =SUM(F61:J61) -> 0
F62: =SUMIF($E$10:$E$39,E62,$M$9:$M$39)+SUMIF($E$10:$E$39,E62,$O$9:$O$39) -> 0 | H62: =SUMIF($E$10:$E$39,E62,$Q$9:$Q$39)+SUMIF($E$10:$E$39,E62,$R$9:$R$39) -> 0 | I62: =SUMIF($E$10:$E$39,E62,$T$9:$T$39) -> 0 | J62: =SUMIF($E$10:$E$39,E62,$S$9:$S$39) -> 0 | K62: =SUM(F62:J62) -> 0
F63: =SUMIF($E$10:$E$39,E63,$M$9:$M$39)+SUMIF($E$10:$E$39,E63,$O$9:$O$39) -> 0 | H63: =SUMIF($E$10:$E$39,E63,$Q$9:$Q$39)+SUMIF($E$10:$E$39,E63,$R$9:$R$39) -> 0 | I63: =SUMIF($E$10:$E$39,E63,$T$9:$T$39) -> 0 | J63: =SUMIF($E$10:$E$39,E63,$S$9:$S$39) -> 0 | K63: =SUM(F63:J63) -> 0
...

Sheet Talent - Indep. Contract
B7: ITEM # | C7: PO # | D7: Invoice # | E7: Invoice Date | F7: Pay Period (WE) | G7: Gross Wages | H7: Mileage | I7: Kit Rental | J7: Other | K7: Total Ineligible | L7: Submitted Amount $ | M7: Crew Name | N7: Crew Position | O7: Valid DTR Form | P7: Pymt Method | Q7: Pymt # | R7: Proof of Payment? | S7: Payment Entity | T7: Type | U7: Description | V7: Address | W7: City | X7: State | Y7: Zip | Z7: Contact # | AA7: Qualify? | AB7: Notes:
B8: 1 | G8: 0 | H8: 0 | I8: 0 | J8: 0 | K8: 0 | L8: =SUM(G8:J8)-K8 -> 0
B9: 2 | G9: 0 | H9: 0 | I9: 0 | J9: 0 | K9: 0 | L9: =SUM(G9:J9)-K9 -> 0
B10: =B9+1 -> 3 | G10: 0 | H10: 0 | I10: 0 | J10: 0 | K10: 0 | L10: =SUM(G10:J10)-K10 -> 0
B11: =B10+1 -> 4 | G11: 0 | H11: 0 | I11: 0 | J11: 0 | K11: 0 | L11: =SUM(G11:J11)-K11 -> 0
B12: =B11+1 -> 5 | G12: 0 | H12: 0 | I12: 0 | J12: 0 | K12: 0 | L12: =SUM(G12:J12)-K12 -> 0
B13: =B12+1 -> 6 | G13: 0 | H13: 0 | I13: 0 | J13: 0 | K13: 0 | L13: =SUM(G13:J13)-K13 -> 0
B14: =B13+1 -> 7 | G14: 0 | H14: 0 | I14: 0 | J14: 0 | K14: 0 | L14: =SUM(G14:J14)-K14 -> 0
B15: =B14+1 -> 8 | G15: 0 | H15: 0 | I15: 0 | J15: 0 | K15: 0 | L15: =SUM(G15:J15)-K15 -> 0
B16: =B15+1 -> 9 | G16: 0 | H16: 0 | I16: 0 | J16: 0 | K16: 0 | L16: =SUM(G16:J16)-K16 -> 0
B17: =B16+1 -> 10 | G17: 0 | H17: 0 | I17: 0 | J17: 0 | K17: 0 | L17: =SUM(G17:J17)-K17 -> 0
B18: =B17+1 -> 11 | G18: 0 | H18: 0 | I18: 0 | J18: 0 | K18: 0 | L18: =SUM(G18:J18)-K18 -> 0
B19: =B18+1 -> 12 | G19: 0 | H19: 0 | I19: 0 | J19: 0 | K19: 0 | L19: =SUM(G19:J19)-K19 -> 0
B20: =B19+1 -> 13 | G20: 0 | H20: 0 | I20: 0 | J20: 0 | K20: 0 | L20: =SUM(G20:J20)-K20 -> 0
B21: =B20+1 -> 14 | G21: 0 | H21: 0 | I21: 0 | J21: 0 | K21: 0 | L21: =SUM(G21:J21)-K21 -> 0
... B37: =B36+1 -> 30 | G37: 0 | H37: 0 | I37: 0 | J37: 0 | K37: 0 | L37: =SUM(G37:J37)-K37 -> 0
G38: 0 | H38: 0 | I38: 0 | J38: 0 | K38: 0 | L38: =SUM(G38:J38)-K38 -> 0
G39: =SUBTOTAL(9,G8:G38) -> 0 | H39: =SUBTOTAL(9,H8:H38) -> 0 | I39: =SUBTOTAL(9,I8:I38) -> 0 | J39: =SUBTOTAL(9,J8:J38) -> 0 | K39: =SUBTOTAL(9,K8:K38) -> 0 | L39: =SUBTOTAL(9,L8:L38) -> 0 | Q39: =SUBTOTAL(2,Q8:Q38) -> 0
G42: =SUM(G8:G38) -> 0 | H42: =SUM(H8:H38) -> 0 | I42: =SUM(I8:I38) -> 0 | J42: =SUM(J8:J38) -> 0 | K42: =SUM(K8:K38) -> 0 | L42: =SUM(L8:L38) -> 0
D46: ELIGIBLE TOTAL | I46: INELIGIBLE TOTAL
D47: NO-OOS | E47: NO-TX | F47: YES | I47: NO-OOS | J47: NO-TX | K47: YES
D48: =SUMIF($AA$8:$AA$37,D47,$L$8:$L$38) -> 0 | E48: =SUMIF($AA$8:$AA$37,E47,$L$8:$L$38) -> 0 | F48: =SUMIF($AA$8:$AA$37,F47,$L$8:$L$37) -> 0 | G48: =SUM(D48:F48) -> 0 | I48: =SUMIF($AA$8:$AA$37,I47,$K$8:$K$37) -> 0 | J48: =SUMIF($AA$8:$AA$37,J47,$K$8:$K$37) -> 0 | K48: =SUMIF($AA$8:$AA$37,K47,$K$8:$K$37) -> 0 | L48: =SUM(I48:K48) -> 0
G49: =L42-G48 -> 0 | L49: =K42-L48 -> 0
H51: Total Eligible | I51: =F48 -> 0
H52: Total Ineligible | I52: =D48+E48+I48+J48+K48 -> 0
H53: Total Expenses | I53: =SUM(I51:I52) -> 0
I54: =G42-I53 -> 0

Sheet AP (POs + Reimbursement)
B8: ITEM # | C8: PO # | D8: Invoice # | E8: Invoice Date | F8: Invoice $ | G8: Total Ineligible | H8: Submitted Amount$ | I8: Vendor Name | J8: Pymt Method | K8: Pymt # | L8: Pay Date | M8: Proof of Payment? | N8: Payment Entity | O8: Type | P8: Description | Q8: Address | R8: City | S8: State | T8: Zip | U8: Contact # | V8: Qualify? | W8: Notes:
B9: 1
B10: 2
B11: 3
B12: 4
B13: 5
B14: 6
B15: 7
B16: 8
B17: 9
B18: 10
B19: 11
B20: 12
... B87: 79
F89: =SUBTOTAL(9,F9:F88) -> 0 | G89: =SUBTOTAL(9,G9:G88) -> 0 | H89: =SUBTOTAL(9,H9:H88) -> 0 | K89: =SUBTOTAL(2,K9:K88) -> 0
G92: SUBMITTED TOTAL | H92: =SUM(H9:H88) -> 0
D96: ELIGIBLE TOTAL | I96: INELIGIBLE TOTAL
D97: NO-OOS | E97: NO-TX | F97: YES | I97: NO-OOS | J97: NO-TX | K97: YES
D98: =SUMIF($V$9:$V$88,D97,$H$9:$H$88) -> 0 | E98: =SUMIF($V$9:$V$88,E97,$H$9:$H$88) -> 0 | F98: =SUMIF($V$9:$V$88,F97,$H$9:$H$88) -> 0 | G98: =SUM(D98:F98) -> 0 | I98: =SUMIF($V$9:$V$88,I97,$G$9:$G$88) -> 0 | J98: =SUMIF($V$9:$V$88,J97,$G$9:$G$88) -> 0 | K98: =SUMIF($V$9:$V$88,K97,$G$9:$G$88) -> 0 | L98: =SUM(I98:K98) -> 0
G99: =H92-G98 -> 0 | L99: =G92-L98 -> #VALUE!
G101: Total Eligible | H101: =F98 -> 0
G102: Total Ineligible | H102: =D98+E98+I98+J98+K98 -> 0
G103: Total Expenses | H103: =SUM(H101:H102) -> 0
H104: =F92-H103 -> 0
G106: Pymt Method | H106: Total | I106: Qualified | J106: Ineligible
G107: Check | H107: =SUMIF($J$9:$J$88,G107,$F$9:$F$88) -> 0 | I107: =SUMIFS($H$9:$H$88,$J$9:$J$88,G107,$V$9:$V$88,"YES") -> 0 | J107: =H107-I107 -> 0
G108: Credit Card | H108: =SUMIF($J$9:$J$88,G108,$F$9:$F$88) -> 0 | I108: =SUMIFS($H$9:$H$88,$J$9:$J$88,G108,$V$9:$V$88,"YES") -> 0 | J108: =H108-I108 -> 0
G109: Unknown | H109: =SUMIF($J$9:$J$88,G109,$F$9:$F$88) -> 0 | I109: =SUMIFS($H$9:$H$88,$J$9:$J$88,G109,$V$9:$V$88,"YES") -> 0 | J109: =H109-I109 -> 0
H110: =SUM(H107:H109) -> 0 | I110: =SUM(I107:I109) -> 0 | J110: =SUM(J107:J109) -> 0
H111: =H110-H103 -> 0 | I111: =I110-H101 -> 0 | J111: =J110-H102 -> 0

Sheet Petty Cash
T5: If no Address, please add PDF file of adress obtained from website
B6: ITEM # | C6: PO # | D6: Env # | E6: Line # | F6: Receipt Date | G6: Petty $ Amount | H6: Total Ineligible | I6: Qualified Total | J6: Name | K6: Pymt Method | L6: Payment Entity | M6: Vendor | N6: Type | O6: Description | P6: Address | Q6: City | R6: State | S6: Zip | T6: Contact # | U6: Qualify? | V6: Notes
B7: 1
B8: 2
B9: 3
B10: 4
B11: 5
B12: 6
B13: 7
B14: 8
B15: 9
B16: 10
B17: 11
B18: 12
... B106: 100
E108: Subtotal: | G108: =SUBTOTAL(9,G7:G107) -> 0
E111: SUBMITTED TOTAL | G111: =SUM(G7:G107) -> 0
E115: ELIGIBLE TOTAL | J115: INELIGIBLE TOTAL
E116: NO-OOS | F116: NO-TX | G116: YES | J116: NO-OOS | K116: NO-TX | L116: YES
E117: =SUMIF($U$7:$U$106,E116,$I$7:$I$106) -> 0 | F117: =SUMIF($U$7:$U$106,F116,$I$7:$I$106) -> 0 | G117: =SUMIF($U$7:$U$106,G116,$I$7:$I$106) -> 0 | H117: =SUM(E117:G117) -> 0 | J117: =SUMIF($U$7:$U$106,J116,$H$7:$H$106) -> 0 | K117: =SUMIF($U$7:$U$106,K116,$H$7:$H$106) -> 0 | L117: =SUMIF($U$7:$U$106,L116,$H$7:$H$106) -> 0 | M117: =SUM(J117:L117) -> 0
H118: =I111-H117 -> 0 | M118: =H111-M117 -> 0
H120: Total Eligible | I120: =G117 -> 0
H121: Total Ineligible | I121: =E117+F117+J117+K117+L117 -> 0
H122: Total Expenses | I122: =SUM(I120:I121) -> 0
J123: =G111-I122 -> 0
E125: Employee Name | F125: Env # | G125: Total | H125: Qualified Amount | I125: Ineligible Amount | J125: Category/Department | K125: Crew Position
G126: =SUMIFS($G$7:$G$107, $J$7:$J$107, E126, $D$7:$D$107, F126) -> 0 | H126: =SUMIFS($I$7:$I$107, $J$7:$J$107, E126, $D$7:$D$107, F126, $U$7:$U$107, "YES") -> 0 | I126: =G126-H126 -> 0
G127: =SUMIFS($G$7:$G$107, $J$7:$J$107, E127, $D$7:$D$107, F127) -> 0 | H127: =SUMIFS($I$7:$I$107, $J$7:$J$107, E127, $D$7:$D$107, F127, $U$7:$U$107, "YES") -> 0 | I127: =G127-H127 -> 0
G128: =SUMIFS($G$7:$G$107, $J$7:$J$107, E128, $D$7:$D$107, F128) -> 0 | H128: =SUMIFS($I$7:$I$107, $J$7:$J$107, E128, $D$7:$D$107, F128, $U$7:$U$107, "YES") -> 0 | I128: =G128-H128 -> 0
G129: =SUMIFS($G$7:$G$107, $J$7:$J$107, E129, $D$7:$D$107, F129) -> 0 | H129: =SUMIFS($I$7:$I$107, $J$7:$J$107, E129, $D$7:$D$107, F129, $U$7:$U$107, "YES") -> 0 | I129: =G129-H129 -> 0
G130: =SUMIFS($G$7:$G$107, $J$7:$J$107, E130, $D$7:$D$107, F130) -> 0 | H130: =SUMIFS($I$7:$I$107, $J$7:$J$107, E130, $D$7:$D$107, F130, $U$7:$U$107, "YES") -> 0 | I130: =G130-H130 -> 0
G131: =SUMIFS($G$7:$G$107, $J$7:$J$107, E131, $D$7:$D$107, F131) -> 0 | H131: =SUMIFS($I$7:$I$107, $J$7:$J$107, E131, $D$7:$D$107, F131, $U$7:$U$107, "YES") -> 0 | I131: =G131-H131 -> 0
G132: =SUMIFS($G$7:$G$107, $J$7:$J$107, E132, $D$7:$D$107, F132) -> 0 | H132: =SUMIFS($I$7:$I$107, $J$7:$J$107, E132, $D$7:$D$107, F132, $U$7:$U$107, "YES") -> 0 | I132: =G132-H132 -> 0
G133: =SUMIFS($G$7:$G$107, $J$7:$J$107, E133, $D$7:$D$107, F133) -> 0 | H133: =SUMIFS($I$7:$I$107, $J$7:$J$107, E133, $D$7:$D$107, F133, $U$7:$U$107, "YES") -> 0 | I133: =G133-H133 -> 0
G134: =SUMIFS($G$7:$G$107, $J$7:$J$107, E134, $D$7:$D$107, F134) -> 0 | H134: =SUMIFS($I$7:$I$107, $J$7:$J$107, E134, $D$7:$D$107, F134, $U$7:$U$107, "YES") -> 0 | I134: =G134-H134 -> 0
F135: Total | G135: =SUM(G126:G134) -> 0 | H135: =SUM(H126:H134) -> 0 | I135: =SUM(I126:I134) -> 0
G136: =G135-G111 -> 0 | H136: =H135-I120 -> 0 | I136: =I135-I121 -> 0

Sheet Agency Vendor Exps
D7: Include | E7: Include | H7: Include | I7: Include | K7: Include | L7: Include
B8: ITEM # | C8: PO # | D8: Invoice # | E8: Invoice Date | F8: Invoice $ | G8: Total Ineligible | H8: Submitted Amount$ | I8: Vendor Name | J8: Pymt Method | K8: Pymt # | L8: Pay Date | M8: Proof of Payment? | N8: Payment Entity | O8: Type | P8: Description | Q8: Address | R8: City | S8: State | T8: Zip | U8: Contact # | V8: Qualify? | W8: Notes: | X8: Job Number
B9: 1 | F9: 0 | G9: 0 | H9: =F9-G9 -> 0
B10: 2 | F10: 0 | G10: 0 | H10: =F10-G10 -> 0
B11: 3 | F11: 0 | G11: 0 | H11: =F11-G11 -> 0
B12: 4 | F12: 0 | G12: 0 | H12: =F12-G12 -> 0
B13: 5 | F13: 0 | G13: 0 | H13: =F13-G13 -> 0
B14: 6 | F14: 0 | G14: 0 | H14: =F14-G14 -> 0
B15: 7 | F15: 0 | G15: 0 | H15: =F15-G15 -> 0
B16: 8 | F16: 0 | G16: 0 | H16: =F16-G16 -> 0
B17: 9 | F17: 0 | G17: 0 | H17: =F17-G17 -> 0
B18: 10 | F18: 0 | G18: 0 | H18: =F18-G18 -> 0
B19: 11 | F19: 0 | G19: 0 | H19: =F19-G19 -> 0
B20: 12 | F20: 0 | G20: 0 | H20: =F20-G20 -> 0
... B28: 20 | F28: 0 | G28: 0 | H28: =F28-G28 -> 0
F29: 0 | G29: 0 | H29: =F29-G29 -> 0
F30: =SUBTOTAL(9,F9:F29) -> 0 | G30: =SUBTOTAL(9,G9:G29) -> 0 | H30: =SUBTOTAL(9,H9:H29) -> 0 | K30: =SUBTOTAL(2,K9:K29) -> 0
F33: =SUM(F9:F29) -> 0 | G33: =SUM(G9:G29) -> 0 | H33: =SUM(H9:H29) -> 0
D37: ELIGIBLE TOTAL | J37: INELIGIBLE TOTAL
D38: NO-OOS | E38: NO-TX | F38: YES | J38: NO-OOS | K38: NO-TX | L38: YES
D39: =SUMIF($V$9:$V$29,D$38,$H$9:$H$29) -> 0 | E39: =SUMIF($V$9:$V$29,E$38,$H$9:$H$29) -> 0 | F39: =SUMIF($V$9:$V$29,F$38,$H$9:$H$29) -> 0 | G39: =SUM(D39:F39) -> 0 | J39: =SUMIF($V$9:$V$27,J$38,$G$9:$G$27) -> 0 | K39: =SUMIF($V$9:$V$27,K$38,$G$9:$G$27) -> 0 | L39: =SUMIF($V$9:$V$27,L$38,$G$9:$G$27) -> 0 | M39: =SUM(J39:L39) -> 0
G40: =H33-G39 -> 0 | M40: =G33-M39 -> 0
G42: Total Eligible | H42: =F39 -> 0
G43: Total Ineligible | H43: =D39+E39+J39+K39+L39 -> 0
G44: Total Expenses | H44: =SUM(H42:H43) -> 0
H45: =F33-H44 -> 0
G48: Pymt Method | H48: Total | I48: Qualified | J48: Ineligible
G49: Check | H49: =SUMIF($J$9:$J$29,G49,$F$9:$F$29) -> 0 | I49: =SUMIFS($H$9:$H$29,$J$9:$J$29,G49,$V$9:$V$29,"YES") -> 0 | J49: =H49-I49 -> 0
G50: Credit Card | H50: =SUMIF($J$9:$J$29,G50,$F$9:$F$29) -> 0 | I50: =SUMIFS($H$9:$H$29,$J$9:$J$29,G50,$V$9:$V$29,"YES") -> 0 | J50: =H50-I50 -> 0
G51: Unknown | H51: =SUMIF($J$9:$J$29,G51,$F$9:$F$29) -> 0 | I51: =SUMIFS($H$9:$H$29,$J$9:$J$29,G51,$V$9:$V$29,"YES") -> 0 | J51: =H51-I51 -> 0
H52: =SUM(H49:H51) -> 0 | I52: =SUM(I49:I51) -> 0 | J52: =SUM(J49:J51) -> 0
H53: =H52-H44 -> 0 | I53: =I52-H42 -> 0 | J53: =J52-H43 -> 0

Sheet Post Production
D7: Include | E7: Include | H7: Include | I7: Include | K7: Include | L7: Include
B8: ITEM # | C8: PO # | D8: Invoice # | E8: Invoice Date | F8: Invoice $ | G8: Total Ineligible | H8: Submitted Amount$ | I8: Vendor Name | J8: Pymt Method | K8: Pymt # | L8: Pay Date | M8: Proof of Payment? | N8: Payment Entity | O8: Type | P8: Description | Q8: Address | R8: City | S8: State | T8: Zip | U8: Contact # | V8: Qualify? | W8: Notes: | X8: Job Number
B9: 1 | F9: 0 | G9: 0 | H9: =F9-G9 -> 0
B10: 2 | F10: 0 | G10: 0 | H10: =F10-G10 -> 0
B11: 3 | F11: 0 | G11: 0 | H11: =F11-G11 -> 0
B12: 4 | F12: 0 | G12: 0 | H12: =F12-G12 -> 0
B13: 5 | F13: 0 | G13: 0 | H13: =F13-G13 -> 0
B14: 6 | F14: 0 | G14: 0 | H14: =F14-G14 -> 0
B15: 7 | F15: 0 | G15: 0 | H15: =F15-G15 -> 0
B16: 8 | F16: 0 | G16: 0 | H16: =F16-G16 -> 0
B17: 9 | F17: 0 | G17: 0 | H17: =F17-G17 -> 0
B18: 10 | F18: 0 | G18: 0 | H18: =F18-G18 -> 0
B19: 11 | F19: 0 | G19: 0 | H19: =F19-G19 -> 0
B20: 12 | F20: 0 | G20: 0 | H20: =F20-G20 -> 0
... B28: 20 | F28: 0 | G28: 0 | H28: =F28-G28 -> 0
F29: 0 | G29: 0 | H29: =F29-G29 -> 0
F30: =SUBTOTAL(9,F9:F29) -> 0 | G30: =SUBTOTAL(9,G9:G29) -> 0 | H30: =SUBTOTAL(9,H9:H29) -> 0 | K30: =SUBTOTAL(2,K9:K29) -> 0
F33: =SUM(F9:F29) -> 0 | G33: =SUM(G9:G29) -> 0 | H33: =SUM(H9:H29) -> 0
D37: ELIGIBLE TOTAL | J37: INELIGIBLE TOTAL
D38: NO-OOS | E38: NO-TX | F38: YES | J38: NO-OOS | K38: NO-TX | L38: YES
D39: =SUMIF($V$9:$V$29,D$38,$H$9:$H$29) -> 0 | E39: =SUMIF($V$9:$V$29,E$38,$H$9:$H$29) -> 0 | F39: =SUMIF($V$9:$V$29,F$38,$H$9:$H$29) -> 0 | G39: =SUM(D39:F39) -> 0 | J39: =SUMIF($V$9:$V$27,J$38,$G$9:$G$27) -> 0 | K39: =SUMIF($V$9:$V$27,K$38,$G$9:$G$27) -> 0 | L39: =SUMIF($V$9:$V$27,L$38,$G$9:$G$27) -> 0 | M39: =SUM(J39:L39) -> 0
G40: =H33-G39 -> 0 | M40: =G33-M39 -> 0
G42: Total Eligible | H42: =F39 -> 0
G43: Total Ineligible | H43: =D39+E39+J39+K39+L39 -> 0
G44: Total Expenses | H44: =SUM(H42:H43) -> 0
H45: =F33-H44 -> 0
G48: Pymt Method | H48: Total | I48: Qualified | J48: Ineligible
G49: Check | H49: =SUMIF($J$9:$J$29,G49,$F$9:$F$29) -> 0 | I49: =SUMIFS($H$9:$H$29,$J$9:$J$29,G49,$V$9:$V$29,"YES") -> 0 | J49: =H49-I49 -> 0
G50: Credit Card | H50: =SUMIF($J$9:$J$29,G50,$F$9:$F$29) -> 0 | I50: =SUMIFS($H$9:$H$29,$J$9:$J$29,G50,$V$9:$V$29,"YES") -> 0 | J50: =H50-I50 -> 0
G51: Unknown | H51: =SUMIF($J$9:$J$29,G51,$F$9:$F$29) -> 0 | I51: =SUMIFS($H$9:$H$29,$J$9:$J$29,G51,$V$9:$V$29,"YES") -> 0 | J51: =H51-I51 -> 0
H52: =SUM(H49:H51) -> 0 | I52: =SUM(I49:I51) -> 0 | J52: =SUM(J49:J51) -> 0
H53: =H52-H44 -> 0 | I53: =I52-H42 -> 0 | J53: =J52-H43 -> 0

Sheet Legend
A1: Ptype | B1: Entity | C1: Value | D1: Payroll Value | E1: Qualify | F1: Description | G1: Comp Description | H1: Payment Entity | I1: Title | AB1: Diversity
A2: Check | B2: ECIS LA | C2: YES | D2: YES | E2: YES | F2: Goods | G2: Session Fee | H2: Elite CIS | I2: Principal | V2: YES | AB2: African American
A3: P-Card | B3: ECIS NC | C3: NO | D3: NO | E3: NO-TX | F3: Services | G3: Holding Fee | H3: =Overview!C13 -> 0 | I3: Extra | V3: NO | AB3: Asian American
A4: Credit Card | B4: ECIS LA | C4: N/A | D4: N/A - (P/R) | E4: NO-OOS | F4: Compensation | G4: Re-use Fee | H4: =Overview!C16 -> 0 | I4: Agent | V4: Incomplete - expired ID | AB4: Caucasian (White) American
A5: Petty Cash | D5: N/A - (OOS) | F5: Other | G5: Cancellation Fee | H5: =Overview!C17 -> 0 | I5: 0 | V5: Incomplete - Missing signature | AB5: Hispanic American
A6: EFT/WIRE | H6: =Overview!C18 -> 0 | AB6: Native American
A7: Payroll Company | H7: =Overview!C19 -> 0 | AB7: Prefer not to Answer
A8: Internal | H8: =Overview!C20 -> 0 | AB8: n/a
A9: Unknown | H9: =Overview!C21 -> 0
H10: =Overview!C22 -> 0
H11: =Overview!C23 -> 0
